2019-04-17 12:48:13 decorators.py[line:89] error(ERROR): Request(192.168.0.39): [POST] Args: /onecity/v1/register? Body: {}
2019-04-17 12:48:13 decorators.py[line:90] error(ERROR): __init__() missing 1 required positional argument: 'model'
Traceback (most recent call last):
  File "/home/ace/flask_api/app/onecity_v1/decorators.py", line 77, in wrapper
    return view(*args, **kwargs)
  File "/home/ace/flask_api/app/onecity_v1/decorators.py", line 108, in wrapper
    return view(*args, **kwargs)
  File "/home/ace/flask_api/app/onecity_v1/validators.py", line 122, in wrapper
    resp = view(*args, **kwargs)
  File "/home/ace/flask_api/app/onecity_v1/validators.py", line 113, in wrapper
    return view(*args, **kwargs)
  File "/home/ace/flask_api/app/onecity_v1/api/register.py", line 16, in post
    user = UserService()
TypeError: __init__() missing 1 required positional argument: 'model'
2019-04-17 12:56:45 decorators.py[line:118] error(ERROR): Request(192.168.0.39): [POST] Args: /onecity/v1/register? Body: {}
2019-04-17 12:56:45 decorators.py[line:119] error(ERROR): __init__() missing 1 required positional argument: 'model'
Traceback (most recent call last):
  File "/home/ace/flask_api/app/onecity_v1/decorators.py", line 106, in wrapper
    return view(*args, **kwargs)
  File "/home/ace/flask_api/app/onecity_v1/decorators.py", line 52, in wrapper
    resp = view(*args, **kwargs)
  File "/home/ace/flask_api/app/onecity_v1/decorators.py", line 44, in wrapper
    return view(*args, **kwargs)
  File "/home/ace/flask_api/app/onecity_v1/api/register.py", line 17, in post
    user = UserService()
TypeError: __init__() missing 1 required positional argument: 'model'
2019-04-17 12:56:57 decorators.py[line:118] error(ERROR): Request(192.168.0.39): [POST] Args: /onecity/v1/register? Body: {}
2019-04-17 12:56:57 decorators.py[line:119] error(ERROR): __init__() missing 1 required positional argument: 'model'
Traceback (most recent call last):
  File "/home/ace/flask_api/app/onecity_v1/decorators.py", line 106, in wrapper
    return view(*args, **kwargs)
  File "/home/ace/flask_api/app/onecity_v1/decorators.py", line 52, in wrapper
    resp = view(*args, **kwargs)
  File "/home/ace/flask_api/app/onecity_v1/decorators.py", line 44, in wrapper
    return view(*args, **kwargs)
  File "/home/ace/flask_api/app/onecity_v1/api/register.py", line 17, in post
    user = UserService()
TypeError: __init__() missing 1 required positional argument: 'model'
2019-04-17 12:57:19 decorators.py[line:118] error(ERROR): Request(192.168.0.39): [POST] Args: /onecity/v1/register? Body: {}
2019-04-17 12:57:19 decorators.py[line:119] error(ERROR): __init__() missing 1 required positional argument: 'model'
Traceback (most recent call last):
  File "/home/ace/flask_api/app/onecity_v1/decorators.py", line 106, in wrapper
    return view(*args, **kwargs)
  File "/home/ace/flask_api/app/onecity_v1/decorators.py", line 52, in wrapper
    resp = view(*args, **kwargs)
  File "/home/ace/flask_api/app/onecity_v1/decorators.py", line 44, in wrapper
    return view(*args, **kwargs)
  File "/home/ace/flask_api/app/onecity_v1/api/register.py", line 17, in post
    user = UserService()
TypeError: __init__() missing 1 required positional argument: 'model'
2019-04-17 12:58:18 decorators.py[line:118] error(ERROR): Request(192.168.0.39): [POST] Args: /onecity/v1/register? Body: {}
2019-04-17 12:58:18 decorators.py[line:119] error(ERROR): post_user() takes 1 positional argument but 2 were given
Traceback (most recent call last):
  File "/home/ace/flask_api/app/onecity_v1/decorators.py", line 106, in wrapper
    return view(*args, **kwargs)
  File "/home/ace/flask_api/app/onecity_v1/decorators.py", line 52, in wrapper
    resp = view(*args, **kwargs)
  File "/home/ace/flask_api/app/onecity_v1/decorators.py", line 44, in wrapper
    return view(*args, **kwargs)
  File "/home/ace/flask_api/app/onecity_v1/api/register.py", line 18, in post
    user.post_user(g.json)
TypeError: post_user() takes 1 positional argument but 2 were given
2019-04-17 13:00:49 decorators.py[line:118] error(ERROR): Request(192.168.0.39): [POST] Args: /onecity/v1/register? Body: {}
2019-04-17 13:00:49 decorators.py[line:119] error(ERROR): __init__() missing 1 required positional argument: 'model'
Traceback (most recent call last):
  File "/home/ace/flask_api/app/onecity_v1/decorators.py", line 106, in wrapper
    return view(*args, **kwargs)
  File "/home/ace/flask_api/app/onecity_v1/decorators.py", line 52, in wrapper
    resp = view(*args, **kwargs)
  File "/home/ace/flask_api/app/onecity_v1/decorators.py", line 44, in wrapper
    return view(*args, **kwargs)
  File "/home/ace/flask_api/app/onecity_v1/api/register.py", line 17, in post
    user = UserService()
TypeError: __init__() missing 1 required positional argument: 'model'
2019-04-17 13:15:54 decorators.py[line:118] error(ERROR): Request(192.168.0.39): [POST] Args: /onecity/v1/register? Body: {}
2019-04-17 13:15:54 decorators.py[line:119] error(ERROR): 'NotFound' object has no attribute 'get_url_no_param'
Traceback (most recent call last):
  File "/home/ace/flask_api/app/onecity_v1/decorators.py", line 106, in wrapper
    return view(*args, **kwargs)
  File "/home/ace/flask_api/app/onecity_v1/decorators.py", line 52, in wrapper
    resp = view(*args, **kwargs)
  File "/home/ace/flask_api/app/onecity_v1/decorators.py", line 44, in wrapper
    return view(*args, **kwargs)
  File "/home/ace/flask_api/app/onecity_v1/api/register.py", line 18, in post
    user.post_user(g.json)
  File "/home/ace/flask_api/app/services/user.py", line 9, in post_user
    raise NotFound()
  File "/home/ace/flask_api/app/libs/error_code.py", line 94, in __init__
    request=request.method + '  ' + self.get_url_no_param()
AttributeError: 'NotFound' object has no attribute 'get_url_no_param'
2019-04-17 13:16:04 decorators.py[line:118] error(ERROR): Request(192.168.0.39): [POST] Args: /onecity/v1/register? Body: {}
2019-04-17 13:16:04 decorators.py[line:119] error(ERROR): 404 Not Found: None
Traceback (most recent call last):
  File "/home/ace/flask_api/app/onecity_v1/decorators.py", line 106, in wrapper
    return view(*args, **kwargs)
  File "/home/ace/flask_api/app/onecity_v1/decorators.py", line 52, in wrapper
    resp = view(*args, **kwargs)
  File "/home/ace/flask_api/app/onecity_v1/decorators.py", line 44, in wrapper
    return view(*args, **kwargs)
  File "/home/ace/flask_api/app/onecity_v1/api/register.py", line 18, in post
    user.post_user(g.json)
  File "/home/ace/flask_api/app/services/user.py", line 9, in post_user
    raise NotFound()
app.libs.error_code.NotFound: 404 Not Found: None
2019-04-17 13:17:29 decorators.py[line:118] error(ERROR): Request(192.168.0.39): [POST] Args: /onecity/v1/register? Body: {}
2019-04-17 13:17:29 decorators.py[line:119] error(ERROR): 404 Not Found: None
Traceback (most recent call last):
  File "/home/ace/flask_api/app/onecity_v1/decorators.py", line 106, in wrapper
    return view(*args, **kwargs)
  File "/home/ace/flask_api/app/onecity_v1/decorators.py", line 52, in wrapper
    resp = view(*args, **kwargs)
  File "/home/ace/flask_api/app/onecity_v1/decorators.py", line 44, in wrapper
    return view(*args, **kwargs)
  File "/home/ace/flask_api/app/onecity_v1/api/register.py", line 18, in post
    user.post_user(g.json)
  File "/home/ace/flask_api/app/services/user.py", line 9, in post_user
    raise NotFound()
app.libs.error_code.NotFound: 404 Not Found: None
2019-04-17 13:17:30 decorators.py[line:118] error(ERROR): Request(192.168.0.39): [POST] Args: /onecity/v1/register? Body: {}
2019-04-17 13:17:30 decorators.py[line:119] error(ERROR): 404 Not Found: None
Traceback (most recent call last):
  File "/home/ace/flask_api/app/onecity_v1/decorators.py", line 106, in wrapper
    return view(*args, **kwargs)
  File "/home/ace/flask_api/app/onecity_v1/decorators.py", line 52, in wrapper
    resp = view(*args, **kwargs)
  File "/home/ace/flask_api/app/onecity_v1/decorators.py", line 44, in wrapper
    return view(*args, **kwargs)
  File "/home/ace/flask_api/app/onecity_v1/api/register.py", line 18, in post
    user.post_user(g.json)
  File "/home/ace/flask_api/app/services/user.py", line 9, in post_user
    raise NotFound()
app.libs.error_code.NotFound: 404 Not Found: None
2019-04-17 13:17:51 decorators.py[line:118] error(ERROR): Request(192.168.0.39): [POST] Args: /onecity/v1/register? Body: {}
2019-04-17 13:17:51 decorators.py[line:119] error(ERROR): 404 Not Found: None
Traceback (most recent call last):
  File "/home/ace/flask_api/app/onecity_v1/decorators.py", line 106, in wrapper
    return view(*args, **kwargs)
  File "/home/ace/flask_api/app/onecity_v1/decorators.py", line 52, in wrapper
    resp = view(*args, **kwargs)
  File "/home/ace/flask_api/app/onecity_v1/decorators.py", line 44, in wrapper
    return view(*args, **kwargs)
  File "/home/ace/flask_api/app/onecity_v1/api/register.py", line 18, in post
    user.post_user(g.json)
  File "/home/ace/flask_api/app/services/user.py", line 9, in post_user
    raise NotFound()
app.libs.error_code.NotFound: 404 Not Found: None
2019-04-17 13:18:18 decorators.py[line:118] error(ERROR): Request(192.168.0.39): [POST] Args: /onecity/v1/register? Body: {}
2019-04-17 13:18:18 decorators.py[line:119] error(ERROR): 404 Not Found: None
Traceback (most recent call last):
  File "/home/ace/flask_api/app/onecity_v1/decorators.py", line 106, in wrapper
    return view(*args, **kwargs)
  File "/home/ace/flask_api/app/onecity_v1/decorators.py", line 52, in wrapper
    resp = view(*args, **kwargs)
  File "/home/ace/flask_api/app/onecity_v1/decorators.py", line 44, in wrapper
    return view(*args, **kwargs)
  File "/home/ace/flask_api/app/onecity_v1/api/register.py", line 18, in post
    user.post_user(g.json)
  File "/home/ace/flask_api/app/services/user.py", line 9, in post_user
    raise NotFound()
app.libs.error_code.NotFound: 404 Not Found: None
2019-04-17 13:21:31 decorators.py[line:118] error(ERROR): Request(192.168.0.39): [POST] Args: /onecity/v1/register? Body: {}
2019-04-17 13:21:31 decorators.py[line:119] error(ERROR): __init__() missing 1 required positional argument: 'msg'
Traceback (most recent call last):
  File "/home/ace/flask_api/app/onecity_v1/decorators.py", line 106, in wrapper
    return view(*args, **kwargs)
  File "/home/ace/flask_api/app/onecity_v1/decorators.py", line 52, in wrapper
    resp = view(*args, **kwargs)
  File "/home/ace/flask_api/app/onecity_v1/decorators.py", line 44, in wrapper
    return view(*args, **kwargs)
  File "/home/ace/flask_api/app/onecity_v1/api/register.py", line 18, in post
    user.post_user(g.json)
  File "/home/ace/flask_api/app/services/user.py", line 9, in post_user
    raise NotFound()
TypeError: __init__() missing 1 required positional argument: 'msg'
2019-04-17 13:21:32 decorators.py[line:118] error(ERROR): Request(192.168.0.39): [POST] Args: /onecity/v1/register? Body: {}
2019-04-17 13:21:32 decorators.py[line:119] error(ERROR): __init__() missing 1 required positional argument: 'msg'
Traceback (most recent call last):
  File "/home/ace/flask_api/app/onecity_v1/decorators.py", line 106, in wrapper
    return view(*args, **kwargs)
  File "/home/ace/flask_api/app/onecity_v1/decorators.py", line 52, in wrapper
    resp = view(*args, **kwargs)
  File "/home/ace/flask_api/app/onecity_v1/decorators.py", line 44, in wrapper
    return view(*args, **kwargs)
  File "/home/ace/flask_api/app/onecity_v1/api/register.py", line 18, in post
    user.post_user(g.json)
  File "/home/ace/flask_api/app/services/user.py", line 9, in post_user
    raise NotFound()
TypeError: __init__() missing 1 required positional argument: 'msg'
2019-04-17 13:21:48 decorators.py[line:118] error(ERROR): Request(192.168.0.39): [POST] Args: /onecity/v1/register? Body: {}
2019-04-17 13:21:48 decorators.py[line:119] error(ERROR): __init__() missing 1 required positional argument: 'msg'
Traceback (most recent call last):
  File "/home/ace/flask_api/app/onecity_v1/decorators.py", line 106, in wrapper
    return view(*args, **kwargs)
  File "/home/ace/flask_api/app/onecity_v1/decorators.py", line 52, in wrapper
    resp = view(*args, **kwargs)
  File "/home/ace/flask_api/app/onecity_v1/decorators.py", line 44, in wrapper
    return view(*args, **kwargs)
  File "/home/ace/flask_api/app/onecity_v1/api/register.py", line 18, in post
    user.post_user(g.json)
  File "/home/ace/flask_api/app/services/user.py", line 9, in post_user
    raise NotFound()
TypeError: __init__() missing 1 required positional argument: 'msg'
2019-04-17 13:21:52 decorators.py[line:118] error(ERROR): Request(192.168.0.39): [POST] Args: /onecity/v1/register? Body: {}
2019-04-17 13:21:52 decorators.py[line:119] error(ERROR): __init__() missing 1 required positional argument: 'msg'
Traceback (most recent call last):
  File "/home/ace/flask_api/app/onecity_v1/decorators.py", line 106, in wrapper
    return view(*args, **kwargs)
  File "/home/ace/flask_api/app/onecity_v1/decorators.py", line 52, in wrapper
    resp = view(*args, **kwargs)
  File "/home/ace/flask_api/app/onecity_v1/decorators.py", line 44, in wrapper
    return view(*args, **kwargs)
  File "/home/ace/flask_api/app/onecity_v1/api/register.py", line 18, in post
    user.post_user(g.json)
  File "/home/ace/flask_api/app/services/user.py", line 9, in post_user
    raise NotFound()
TypeError: __init__() missing 1 required positional argument: 'msg'
2019-04-17 13:22:27 decorators.py[line:118] error(ERROR): Request(192.168.0.39): [POST] Args: /onecity/v1/register? Body: {}
2019-04-17 13:22:27 decorators.py[line:119] error(ERROR): 404 Not Found: None
Traceback (most recent call last):
  File "/home/ace/flask_api/app/onecity_v1/decorators.py", line 106, in wrapper
    return view(*args, **kwargs)
  File "/home/ace/flask_api/app/onecity_v1/decorators.py", line 52, in wrapper
    resp = view(*args, **kwargs)
  File "/home/ace/flask_api/app/onecity_v1/decorators.py", line 44, in wrapper
    return view(*args, **kwargs)
  File "/home/ace/flask_api/app/onecity_v1/api/register.py", line 18, in post
    user.post_user(g.json)
  File "/home/ace/flask_api/app/services/user.py", line 9, in post_user
    raise NotFound()
app.libs.error_code.NotFound: 404 Not Found: None
2019-04-17 13:26:23 decorators.py[line:118] error(ERROR): Request(192.168.0.39): [POST] Args: /onecity/v1/register? Body: {}
2019-04-17 13:26:23 decorators.py[line:119] error(ERROR): 404 Not Found: None
Traceback (most recent call last):
  File "/home/ace/flask_api/app/onecity_v1/decorators.py", line 106, in wrapper
    return view(*args, **kwargs)
  File "/home/ace/flask_api/app/onecity_v1/decorators.py", line 52, in wrapper
    resp = view(*args, **kwargs)
  File "/home/ace/flask_api/app/onecity_v1/decorators.py", line 44, in wrapper
    return view(*args, **kwargs)
  File "/home/ace/flask_api/app/onecity_v1/api/register.py", line 18, in post
    user.post_user(g.json)
  File "/home/ace/flask_api/app/services/user.py", line 9, in post_user
    raise NotFound()
app.libs.error_code.NotFound: 404 Not Found: None
2019-04-17 14:04:22 decorators.py[line:118] error(ERROR): Request(192.168.0.39): [POST] Args: /onecity/v1/register? Body: {}
2019-04-17 14:04:22 decorators.py[line:119] error(ERROR): 404 Not Found: None
Traceback (most recent call last):
  File "/home/ace/flask_api/app/onecity_v1/decorators.py", line 106, in wrapper
    return view(*args, **kwargs)
  File "/home/ace/flask_api/app/onecity_v1/decorators.py", line 52, in wrapper
    resp = view(*args, **kwargs)
  File "/home/ace/flask_api/app/onecity_v1/decorators.py", line 44, in wrapper
    return view(*args, **kwargs)
  File "/home/ace/flask_api/app/onecity_v1/api/register.py", line 18, in post
    user.post_user(g.json)
  File "/home/ace/flask_api/app/services/user.py", line 9, in post_user
    raise NotFound()
app.libs.error_code.NotFound: 404 Not Found: None
2019-04-17 14:05:37 decorators.py[line:118] error(ERROR): Request(192.168.0.39): [POST] Args: /onecity/v1/register? Body: {}
2019-04-17 14:05:37 decorators.py[line:119] error(ERROR): 404 Not Found: None
Traceback (most recent call last):
  File "/home/ace/flask_api/app/onecity_v1/decorators.py", line 106, in wrapper
    return view(*args, **kwargs)
  File "/home/ace/flask_api/app/onecity_v1/decorators.py", line 52, in wrapper
    resp = view(*args, **kwargs)
  File "/home/ace/flask_api/app/onecity_v1/decorators.py", line 44, in wrapper
    return view(*args, **kwargs)
  File "/home/ace/flask_api/app/onecity_v1/api/register.py", line 18, in post
    user.post_user(g.json)
  File "/home/ace/flask_api/app/services/user.py", line 9, in post_user
    raise NotFound()
app.libs.error_code.NotFound: 404 Not Found: None
2019-04-17 14:06:23 decorators.py[line:118] error(ERROR): Request(192.168.0.39): [POST] Args: /onecity/v1/register? Body: {}
2019-04-17 14:06:23 decorators.py[line:119] error(ERROR): 404 Not Found: None
Traceback (most recent call last):
  File "/home/ace/flask_api/app/onecity_v1/decorators.py", line 106, in wrapper
    return view(*args, **kwargs)
  File "/home/ace/flask_api/app/onecity_v1/decorators.py", line 52, in wrapper
    resp = view(*args, **kwargs)
  File "/home/ace/flask_api/app/onecity_v1/decorators.py", line 44, in wrapper
    return view(*args, **kwargs)
  File "/home/ace/flask_api/app/onecity_v1/api/register.py", line 18, in post
    user.post_user(g.json)
  File "/home/ace/flask_api/app/services/user.py", line 9, in post_user
    raise NotFound()
app.libs.error_code.NotFound: 404 Not Found: None
2019-04-17 14:06:56 decorators.py[line:118] error(ERROR): Request(192.168.0.39): [POST] Args: /onecity/v1/register? Body: {}
2019-04-17 14:06:56 decorators.py[line:119] error(ERROR): 404 Not Found: None
Traceback (most recent call last):
  File "/home/ace/flask_api/app/onecity_v1/decorators.py", line 106, in wrapper
    return view(*args, **kwargs)
  File "/home/ace/flask_api/app/onecity_v1/decorators.py", line 52, in wrapper
    resp = view(*args, **kwargs)
  File "/home/ace/flask_api/app/onecity_v1/decorators.py", line 44, in wrapper
    return view(*args, **kwargs)
  File "/home/ace/flask_api/app/onecity_v1/api/register.py", line 18, in post
    user.post_user(g.json)
  File "/home/ace/flask_api/app/services/user.py", line 9, in post_user
    raise NotFound()
app.libs.error_code.NotFound: 404 Not Found: None
2019-04-17 14:08:18 decorators.py[line:118] error(ERROR): Request(192.168.0.39): [POST] Args: /onecity/v1/register? Body: {}
2019-04-17 14:08:18 decorators.py[line:119] error(ERROR): 404 Not Found: None
Traceback (most recent call last):
  File "/home/ace/flask_api/app/onecity_v1/decorators.py", line 106, in wrapper
    return view(*args, **kwargs)
  File "/home/ace/flask_api/app/onecity_v1/decorators.py", line 52, in wrapper
    resp = view(*args, **kwargs)
  File "/home/ace/flask_api/app/onecity_v1/decorators.py", line 44, in wrapper
    return view(*args, **kwargs)
  File "/home/ace/flask_api/app/onecity_v1/api/register.py", line 18, in post
    user.post_user(g.json)
  File "/home/ace/flask_api/app/services/user.py", line 9, in post_user
    raise NotFound()
app.libs.error_code.NotFound: 404 Not Found: None
2019-04-17 14:10:30 decorators.py[line:118] error(ERROR): Request(192.168.0.39): [POST] Args: /onecity/v1/register? Body: {}
2019-04-17 14:10:30 decorators.py[line:119] error(ERROR): 404 Not Found: None
Traceback (most recent call last):
  File "/home/ace/flask_api/app/onecity_v1/decorators.py", line 106, in wrapper
    return view(*args, **kwargs)
  File "/home/ace/flask_api/app/onecity_v1/decorators.py", line 52, in wrapper
    resp = view(*args, **kwargs)
  File "/home/ace/flask_api/app/onecity_v1/decorators.py", line 44, in wrapper
    return view(*args, **kwargs)
  File "/home/ace/flask_api/app/onecity_v1/api/register.py", line 18, in post
    user.post_user(g.json)
  File "/home/ace/flask_api/app/services/user.py", line 9, in post_user
    raise NotFound()
app.libs.error_code.NotFound: 404 Not Found: None
2019-04-17 14:10:42 decorators.py[line:118] error(ERROR): Request(192.168.0.39): [POST] Args: /onecity/v1/register? Body: {}
2019-04-17 14:10:42 decorators.py[line:119] error(ERROR): 404 Not Found: None
Traceback (most recent call last):
  File "/home/ace/flask_api/app/onecity_v1/decorators.py", line 106, in wrapper
    return view(*args, **kwargs)
  File "/home/ace/flask_api/app/onecity_v1/decorators.py", line 52, in wrapper
    resp = view(*args, **kwargs)
  File "/home/ace/flask_api/app/onecity_v1/decorators.py", line 44, in wrapper
    return view(*args, **kwargs)
  File "/home/ace/flask_api/app/onecity_v1/api/register.py", line 18, in post
    user.post_user(g.json)
  File "/home/ace/flask_api/app/services/user.py", line 9, in post_user
    raise NotFound()
app.libs.error_code.NotFound: 404 Not Found: None
2019-04-17 14:10:42 decorators.py[line:118] error(ERROR): Request(192.168.0.39): [POST] Args: /onecity/v1/register? Body: {}
2019-04-17 14:10:42 decorators.py[line:119] error(ERROR): 404 Not Found: None
Traceback (most recent call last):
  File "/home/ace/flask_api/app/onecity_v1/decorators.py", line 106, in wrapper
    return view(*args, **kwargs)
  File "/home/ace/flask_api/app/onecity_v1/decorators.py", line 52, in wrapper
    resp = view(*args, **kwargs)
  File "/home/ace/flask_api/app/onecity_v1/decorators.py", line 44, in wrapper
    return view(*args, **kwargs)
  File "/home/ace/flask_api/app/onecity_v1/api/register.py", line 18, in post
    user.post_user(g.json)
  File "/home/ace/flask_api/app/services/user.py", line 9, in post_user
    raise NotFound()
app.libs.error_code.NotFound: 404 Not Found: None
2019-04-17 14:10:43 decorators.py[line:118] error(ERROR): Request(192.168.0.39): [POST] Args: /onecity/v1/register? Body: {}
2019-04-17 14:10:43 decorators.py[line:119] error(ERROR): 404 Not Found: None
Traceback (most recent call last):
  File "/home/ace/flask_api/app/onecity_v1/decorators.py", line 106, in wrapper
    return view(*args, **kwargs)
  File "/home/ace/flask_api/app/onecity_v1/decorators.py", line 52, in wrapper
    resp = view(*args, **kwargs)
  File "/home/ace/flask_api/app/onecity_v1/decorators.py", line 44, in wrapper
    return view(*args, **kwargs)
  File "/home/ace/flask_api/app/onecity_v1/api/register.py", line 18, in post
    user.post_user(g.json)
  File "/home/ace/flask_api/app/services/user.py", line 9, in post_user
    raise NotFound()
app.libs.error_code.NotFound: 404 Not Found: None
2019-04-17 14:10:44 decorators.py[line:118] error(ERROR): Request(192.168.0.39): [POST] Args: /onecity/v1/register? Body: {}
2019-04-17 14:10:44 decorators.py[line:119] error(ERROR): 404 Not Found: None
Traceback (most recent call last):
  File "/home/ace/flask_api/app/onecity_v1/decorators.py", line 106, in wrapper
    return view(*args, **kwargs)
  File "/home/ace/flask_api/app/onecity_v1/decorators.py", line 52, in wrapper
    resp = view(*args, **kwargs)
  File "/home/ace/flask_api/app/onecity_v1/decorators.py", line 44, in wrapper
    return view(*args, **kwargs)
  File "/home/ace/flask_api/app/onecity_v1/api/register.py", line 18, in post
    user.post_user(g.json)
  File "/home/ace/flask_api/app/services/user.py", line 9, in post_user
    raise NotFound()
app.libs.error_code.NotFound: 404 Not Found: None
2019-04-17 14:10:45 decorators.py[line:118] error(ERROR): Request(192.168.0.39): [POST] Args: /onecity/v1/register? Body: {}
2019-04-17 14:10:45 decorators.py[line:119] error(ERROR): 404 Not Found: None
Traceback (most recent call last):
  File "/home/ace/flask_api/app/onecity_v1/decorators.py", line 106, in wrapper
    return view(*args, **kwargs)
  File "/home/ace/flask_api/app/onecity_v1/decorators.py", line 52, in wrapper
    resp = view(*args, **kwargs)
  File "/home/ace/flask_api/app/onecity_v1/decorators.py", line 44, in wrapper
    return view(*args, **kwargs)
  File "/home/ace/flask_api/app/onecity_v1/api/register.py", line 18, in post
    user.post_user(g.json)
  File "/home/ace/flask_api/app/services/user.py", line 9, in post_user
    raise NotFound()
app.libs.error_code.NotFound: 404 Not Found: None
2019-04-17 14:10:45 decorators.py[line:118] error(ERROR): Request(192.168.0.39): [POST] Args: /onecity/v1/register? Body: {}
2019-04-17 14:10:45 decorators.py[line:119] error(ERROR): 404 Not Found: None
Traceback (most recent call last):
  File "/home/ace/flask_api/app/onecity_v1/decorators.py", line 106, in wrapper
    return view(*args, **kwargs)
  File "/home/ace/flask_api/app/onecity_v1/decorators.py", line 52, in wrapper
    resp = view(*args, **kwargs)
  File "/home/ace/flask_api/app/onecity_v1/decorators.py", line 44, in wrapper
    return view(*args, **kwargs)
  File "/home/ace/flask_api/app/onecity_v1/api/register.py", line 18, in post
    user.post_user(g.json)
  File "/home/ace/flask_api/app/services/user.py", line 9, in post_user
    raise NotFound()
app.libs.error_code.NotFound: 404 Not Found: None
2019-04-17 14:10:58 decorators.py[line:118] error(ERROR): Request(192.168.0.39): [POST] Args: /onecity/v1/register? Body: {}
2019-04-17 14:10:58 decorators.py[line:119] error(ERROR): 404 Not Found: None
Traceback (most recent call last):
  File "/home/ace/flask_api/app/onecity_v1/decorators.py", line 106, in wrapper
    return view(*args, **kwargs)
  File "/home/ace/flask_api/app/onecity_v1/decorators.py", line 52, in wrapper
    resp = view(*args, **kwargs)
  File "/home/ace/flask_api/app/onecity_v1/decorators.py", line 44, in wrapper
    return view(*args, **kwargs)
  File "/home/ace/flask_api/app/onecity_v1/api/register.py", line 18, in post
    user.post_user(g.json)
  File "/home/ace/flask_api/app/services/user.py", line 9, in post_user
    raise NotFound()
app.libs.error_code.NotFound: 404 Not Found: None
2019-04-17 14:10:58 decorators.py[line:118] error(ERROR): Request(192.168.0.39): [POST] Args: /onecity/v1/register? Body: {}
2019-04-17 14:10:58 decorators.py[line:119] error(ERROR): 404 Not Found: None
Traceback (most recent call last):
  File "/home/ace/flask_api/app/onecity_v1/decorators.py", line 106, in wrapper
    return view(*args, **kwargs)
  File "/home/ace/flask_api/app/onecity_v1/decorators.py", line 52, in wrapper
    resp = view(*args, **kwargs)
  File "/home/ace/flask_api/app/onecity_v1/decorators.py", line 44, in wrapper
    return view(*args, **kwargs)
  File "/home/ace/flask_api/app/onecity_v1/api/register.py", line 18, in post
    user.post_user(g.json)
  File "/home/ace/flask_api/app/services/user.py", line 9, in post_user
    raise NotFound()
app.libs.error_code.NotFound: 404 Not Found: None
2019-04-17 14:10:59 decorators.py[line:118] error(ERROR): Request(192.168.0.39): [POST] Args: /onecity/v1/register? Body: {}
2019-04-17 14:10:59 decorators.py[line:119] error(ERROR): 404 Not Found: None
Traceback (most recent call last):
  File "/home/ace/flask_api/app/onecity_v1/decorators.py", line 106, in wrapper
    return view(*args, **kwargs)
  File "/home/ace/flask_api/app/onecity_v1/decorators.py", line 52, in wrapper
    resp = view(*args, **kwargs)
  File "/home/ace/flask_api/app/onecity_v1/decorators.py", line 44, in wrapper
    return view(*args, **kwargs)
  File "/home/ace/flask_api/app/onecity_v1/api/register.py", line 18, in post
    user.post_user(g.json)
  File "/home/ace/flask_api/app/services/user.py", line 9, in post_user
    raise NotFound()
app.libs.error_code.NotFound: 404 Not Found: None
2019-04-17 14:10:59 decorators.py[line:118] error(ERROR): Request(192.168.0.39): [POST] Args: /onecity/v1/register? Body: {}
2019-04-17 14:10:59 decorators.py[line:119] error(ERROR): 404 Not Found: None
Traceback (most recent call last):
  File "/home/ace/flask_api/app/onecity_v1/decorators.py", line 106, in wrapper
    return view(*args, **kwargs)
  File "/home/ace/flask_api/app/onecity_v1/decorators.py", line 52, in wrapper
    resp = view(*args, **kwargs)
  File "/home/ace/flask_api/app/onecity_v1/decorators.py", line 44, in wrapper
    return view(*args, **kwargs)
  File "/home/ace/flask_api/app/onecity_v1/api/register.py", line 18, in post
    user.post_user(g.json)
  File "/home/ace/flask_api/app/services/user.py", line 9, in post_user
    raise NotFound()
app.libs.error_code.NotFound: 404 Not Found: None
2019-04-17 14:10:59 decorators.py[line:118] error(ERROR): Request(192.168.0.39): [POST] Args: /onecity/v1/register? Body: {}
2019-04-17 14:10:59 decorators.py[line:119] error(ERROR): 404 Not Found: None
Traceback (most recent call last):
  File "/home/ace/flask_api/app/onecity_v1/decorators.py", line 106, in wrapper
    return view(*args, **kwargs)
  File "/home/ace/flask_api/app/onecity_v1/decorators.py", line 52, in wrapper
    resp = view(*args, **kwargs)
  File "/home/ace/flask_api/app/onecity_v1/decorators.py", line 44, in wrapper
    return view(*args, **kwargs)
  File "/home/ace/flask_api/app/onecity_v1/api/register.py", line 18, in post
    user.post_user(g.json)
  File "/home/ace/flask_api/app/services/user.py", line 9, in post_user
    raise NotFound()
app.libs.error_code.NotFound: 404 Not Found: None
2019-04-17 14:11:00 decorators.py[line:118] error(ERROR): Request(192.168.0.39): [POST] Args: /onecity/v1/register? Body: {}
2019-04-17 14:11:00 decorators.py[line:119] error(ERROR): 404 Not Found: None
Traceback (most recent call last):
  File "/home/ace/flask_api/app/onecity_v1/decorators.py", line 106, in wrapper
    return view(*args, **kwargs)
  File "/home/ace/flask_api/app/onecity_v1/decorators.py", line 52, in wrapper
    resp = view(*args, **kwargs)
  File "/home/ace/flask_api/app/onecity_v1/decorators.py", line 44, in wrapper
    return view(*args, **kwargs)
  File "/home/ace/flask_api/app/onecity_v1/api/register.py", line 18, in post
    user.post_user(g.json)
  File "/home/ace/flask_api/app/services/user.py", line 9, in post_user
    raise NotFound()
app.libs.error_code.NotFound: 404 Not Found: None
2019-04-17 14:11:00 decorators.py[line:118] error(ERROR): Request(192.168.0.39): [POST] Args: /onecity/v1/register? Body: {}
2019-04-17 14:11:00 decorators.py[line:119] error(ERROR): 404 Not Found: None
Traceback (most recent call last):
  File "/home/ace/flask_api/app/onecity_v1/decorators.py", line 106, in wrapper
    return view(*args, **kwargs)
  File "/home/ace/flask_api/app/onecity_v1/decorators.py", line 52, in wrapper
    resp = view(*args, **kwargs)
  File "/home/ace/flask_api/app/onecity_v1/decorators.py", line 44, in wrapper
    return view(*args, **kwargs)
  File "/home/ace/flask_api/app/onecity_v1/api/register.py", line 18, in post
    user.post_user(g.json)
  File "/home/ace/flask_api/app/services/user.py", line 9, in post_user
    raise NotFound()
app.libs.error_code.NotFound: 404 Not Found: None
2019-04-17 14:11:00 decorators.py[line:118] error(ERROR): Request(192.168.0.39): [POST] Args: /onecity/v1/register? Body: {}
2019-04-17 14:11:00 decorators.py[line:119] error(ERROR): 404 Not Found: None
Traceback (most recent call last):
  File "/home/ace/flask_api/app/onecity_v1/decorators.py", line 106, in wrapper
    return view(*args, **kwargs)
  File "/home/ace/flask_api/app/onecity_v1/decorators.py", line 52, in wrapper
    resp = view(*args, **kwargs)
  File "/home/ace/flask_api/app/onecity_v1/decorators.py", line 44, in wrapper
    return view(*args, **kwargs)
  File "/home/ace/flask_api/app/onecity_v1/api/register.py", line 18, in post
    user.post_user(g.json)
  File "/home/ace/flask_api/app/services/user.py", line 9, in post_user
    raise NotFound()
app.libs.error_code.NotFound: 404 Not Found: None
2019-04-17 14:11:00 decorators.py[line:118] error(ERROR): Request(192.168.0.39): [POST] Args: /onecity/v1/register? Body: {}
2019-04-17 14:11:00 decorators.py[line:119] error(ERROR): 404 Not Found: None
Traceback (most recent call last):
  File "/home/ace/flask_api/app/onecity_v1/decorators.py", line 106, in wrapper
    return view(*args, **kwargs)
  File "/home/ace/flask_api/app/onecity_v1/decorators.py", line 52, in wrapper
    resp = view(*args, **kwargs)
  File "/home/ace/flask_api/app/onecity_v1/decorators.py", line 44, in wrapper
    return view(*args, **kwargs)
  File "/home/ace/flask_api/app/onecity_v1/api/register.py", line 18, in post
    user.post_user(g.json)
  File "/home/ace/flask_api/app/services/user.py", line 9, in post_user
    raise NotFound()
app.libs.error_code.NotFound: 404 Not Found: None
2019-04-17 14:11:00 decorators.py[line:118] error(ERROR): Request(192.168.0.39): [POST] Args: /onecity/v1/register? Body: {}
2019-04-17 14:11:00 decorators.py[line:119] error(ERROR): 404 Not Found: None
Traceback (most recent call last):
  File "/home/ace/flask_api/app/onecity_v1/decorators.py", line 106, in wrapper
    return view(*args, **kwargs)
  File "/home/ace/flask_api/app/onecity_v1/decorators.py", line 52, in wrapper
    resp = view(*args, **kwargs)
  File "/home/ace/flask_api/app/onecity_v1/decorators.py", line 44, in wrapper
    return view(*args, **kwargs)
  File "/home/ace/flask_api/app/onecity_v1/api/register.py", line 18, in post
    user.post_user(g.json)
  File "/home/ace/flask_api/app/services/user.py", line 9, in post_user
    raise NotFound()
app.libs.error_code.NotFound: 404 Not Found: None
2019-04-17 14:11:07 decorators.py[line:118] error(ERROR): Request(192.168.0.39): [POST] Args: /onecity/v1/register? Body: {}
2019-04-17 14:11:07 decorators.py[line:119] error(ERROR): 404 Not Found: None
Traceback (most recent call last):
  File "/home/ace/flask_api/app/onecity_v1/decorators.py", line 106, in wrapper
    return view(*args, **kwargs)
  File "/home/ace/flask_api/app/onecity_v1/decorators.py", line 52, in wrapper
    resp = view(*args, **kwargs)
  File "/home/ace/flask_api/app/onecity_v1/decorators.py", line 44, in wrapper
    return view(*args, **kwargs)
  File "/home/ace/flask_api/app/onecity_v1/api/register.py", line 18, in post
    user.post_user(g.json)
  File "/home/ace/flask_api/app/services/user.py", line 9, in post_user
    raise NotFound()
app.libs.error_code.NotFound: 404 Not Found: None
2019-04-17 14:11:41 decorators.py[line:118] error(ERROR): Request(192.168.0.39): [POST] Args: /onecity/v1/register? Body: {}
2019-04-17 14:11:41 decorators.py[line:119] error(ERROR): 404 Not Found: None
Traceback (most recent call last):
  File "/home/ace/flask_api/app/onecity_v1/decorators.py", line 106, in wrapper
    return view(*args, **kwargs)
  File "/home/ace/flask_api/app/onecity_v1/decorators.py", line 52, in wrapper
    resp = view(*args, **kwargs)
  File "/home/ace/flask_api/app/onecity_v1/decorators.py", line 44, in wrapper
    return view(*args, **kwargs)
  File "/home/ace/flask_api/app/onecity_v1/api/register.py", line 18, in post
    user.post_user(g.json)
  File "/home/ace/flask_api/app/services/user.py", line 9, in post_user
    raise NotFound()
app.libs.error_code.NotFound: 404 Not Found: None
2019-04-17 14:12:24 decorators.py[line:118] error(ERROR): Request(192.168.0.39): [POST] Args: /onecity/v1/register? Body: {}
2019-04-17 14:12:24 decorators.py[line:119] error(ERROR): 404 Not Found: None
Traceback (most recent call last):
  File "/home/ace/flask_api/app/onecity_v1/decorators.py", line 106, in wrapper
    return view(*args, **kwargs)
  File "/home/ace/flask_api/app/onecity_v1/decorators.py", line 52, in wrapper
    resp = view(*args, **kwargs)
  File "/home/ace/flask_api/app/onecity_v1/decorators.py", line 44, in wrapper
    return view(*args, **kwargs)
  File "/home/ace/flask_api/app/onecity_v1/api/register.py", line 18, in post
    user.post_user(g.json)
  File "/home/ace/flask_api/app/services/user.py", line 9, in post_user
    raise NotFound()
app.libs.error_code.NotFound: 404 Not Found: None
2019-04-17 14:13:11 decorators.py[line:118] error(ERROR): Request(192.168.0.39): [POST] Args: /onecity/v1/register? Body: {}
2019-04-17 14:13:11 decorators.py[line:119] error(ERROR): 404 Not Found: None
Traceback (most recent call last):
  File "/home/ace/flask_api/app/onecity_v1/decorators.py", line 106, in wrapper
    return view(*args, **kwargs)
  File "/home/ace/flask_api/app/onecity_v1/decorators.py", line 52, in wrapper
    resp = view(*args, **kwargs)
  File "/home/ace/flask_api/app/onecity_v1/decorators.py", line 44, in wrapper
    return view(*args, **kwargs)
  File "/home/ace/flask_api/app/onecity_v1/api/register.py", line 18, in post
    user.post_user(g.json)
  File "/home/ace/flask_api/app/services/user.py", line 9, in post_user
    raise NotFound()
app.libs.error_code.NotFound: 404 Not Found: None
2019-04-17 14:13:30 decorators.py[line:118] error(ERROR): Request(192.168.0.39): [POST] Args: /onecity/v1/register? Body: {}
2019-04-17 14:13:30 decorators.py[line:119] error(ERROR): 404 Not Found: None
Traceback (most recent call last):
  File "/home/ace/flask_api/app/onecity_v1/decorators.py", line 106, in wrapper
    return view(*args, **kwargs)
  File "/home/ace/flask_api/app/onecity_v1/decorators.py", line 52, in wrapper
    resp = view(*args, **kwargs)
  File "/home/ace/flask_api/app/onecity_v1/decorators.py", line 44, in wrapper
    return view(*args, **kwargs)
  File "/home/ace/flask_api/app/onecity_v1/api/register.py", line 18, in post
    user.post_user(g.json)
  File "/home/ace/flask_api/app/services/user.py", line 9, in post_user
    raise NotFound()
app.libs.error_code.NotFound: 404 Not Found: None
2019-04-17 14:18:59 decorators.py[line:118] error(ERROR): Request(192.168.0.39): [POST] Args: /onecity/v1/register? Body: {}
2019-04-17 14:18:59 decorators.py[line:119] error(ERROR): 404 Not Found: None
Traceback (most recent call last):
  File "/home/ace/flask_api/app/onecity_v1/decorators.py", line 106, in wrapper
    return view(*args, **kwargs)
  File "/home/ace/flask_api/app/onecity_v1/decorators.py", line 52, in wrapper
    resp = view(*args, **kwargs)
  File "/home/ace/flask_api/app/onecity_v1/decorators.py", line 44, in wrapper
    return view(*args, **kwargs)
  File "/home/ace/flask_api/app/onecity_v1/api/register.py", line 18, in post
    user.post_user(g.json)
  File "/home/ace/flask_api/app/services/user.py", line 9, in post_user
    raise NotFound()
app.libs.error_code.NotFound: 404 Not Found: None
2019-04-17 14:19:22 decorators.py[line:120] error(ERROR): Request(192.168.0.39): [POST] Args: /onecity/v1/register? Body: {}
2019-04-17 14:19:22 decorators.py[line:121] error(ERROR): 404 Not Found: None
Traceback (most recent call last):
  File "/home/ace/flask_api/app/onecity_v1/decorators.py", line 106, in wrapper
    return view(*args, **kwargs)
  File "/home/ace/flask_api/app/onecity_v1/decorators.py", line 52, in wrapper
    resp = view(*args, **kwargs)
  File "/home/ace/flask_api/app/onecity_v1/decorators.py", line 44, in wrapper
    return view(*args, **kwargs)
  File "/home/ace/flask_api/app/onecity_v1/api/register.py", line 18, in post
    user.post_user(g.json)
  File "/home/ace/flask_api/app/services/user.py", line 9, in post_user
    raise NotFound()
app.libs.error_code.NotFound: 404 Not Found: None
2019-04-17 14:19:28 decorators.py[line:120] error(ERROR): Request(192.168.0.39): [POST] Args: /onecity/v1/register? Body: {}
2019-04-17 14:19:28 decorators.py[line:121] error(ERROR): 404 Not Found: None
Traceback (most recent call last):
  File "/home/ace/flask_api/app/onecity_v1/decorators.py", line 106, in wrapper
    return view(*args, **kwargs)
  File "/home/ace/flask_api/app/onecity_v1/decorators.py", line 52, in wrapper
    resp = view(*args, **kwargs)
  File "/home/ace/flask_api/app/onecity_v1/decorators.py", line 44, in wrapper
    return view(*args, **kwargs)
  File "/home/ace/flask_api/app/onecity_v1/api/register.py", line 18, in post
    user.post_user(g.json)
  File "/home/ace/flask_api/app/services/user.py", line 9, in post_user
    raise NotFound()
app.libs.error_code.NotFound: 404 Not Found: None
2019-04-17 14:19:49 decorators.py[line:120] error(ERROR): Request(192.168.0.39): [POST] Args: /onecity/v1/register? Body: {}
2019-04-17 14:19:49 decorators.py[line:121] error(ERROR): 404 Not Found: None
Traceback (most recent call last):
  File "/home/ace/flask_api/app/onecity_v1/decorators.py", line 106, in wrapper
    return view(*args, **kwargs)
  File "/home/ace/flask_api/app/onecity_v1/decorators.py", line 52, in wrapper
    resp = view(*args, **kwargs)
  File "/home/ace/flask_api/app/onecity_v1/decorators.py", line 44, in wrapper
    return view(*args, **kwargs)
  File "/home/ace/flask_api/app/onecity_v1/api/register.py", line 18, in post
    user.post_user(g.json)
  File "/home/ace/flask_api/app/services/user.py", line 9, in post_user
    raise NotFound()
app.libs.error_code.NotFound: 404 Not Found: None
2019-04-17 14:20:16 decorators.py[line:120] error(ERROR): Request(192.168.0.39): [POST] Args: /onecity/v1/register? Body: {}
2019-04-17 14:20:16 decorators.py[line:121] error(ERROR): 404 Not Found: None
Traceback (most recent call last):
  File "/home/ace/flask_api/app/onecity_v1/decorators.py", line 106, in wrapper
    return view(*args, **kwargs)
  File "/home/ace/flask_api/app/onecity_v1/decorators.py", line 52, in wrapper
    resp = view(*args, **kwargs)
  File "/home/ace/flask_api/app/onecity_v1/decorators.py", line 44, in wrapper
    return view(*args, **kwargs)
  File "/home/ace/flask_api/app/onecity_v1/api/register.py", line 18, in post
    user.post_user(g.json)
  File "/home/ace/flask_api/app/services/user.py", line 9, in post_user
    raise NotFound()
app.libs.error_code.NotFound: 404 Not Found: None
2019-04-17 14:41:04 decorators.py[line:120] error(ERROR): Request(192.168.0.39): [POST] Args: /onecity/v1/register? Body: {}
2019-04-17 14:41:04 decorators.py[line:121] error(ERROR): name 'error_code' is not defined
Traceback (most recent call last):
  File "/home/ace/flask_api/app/onecity_v1/decorators.py", line 106, in wrapper
    return view(*args, **kwargs)
  File "/home/ace/flask_api/app/onecity_v1/decorators.py", line 52, in wrapper
    resp = view(*args, **kwargs)
  File "/home/ace/flask_api/app/onecity_v1/decorators.py", line 44, in wrapper
    return view(*args, **kwargs)
  File "/home/ace/flask_api/app/onecity_v1/api/register.py", line 19, in post
    return Success()
  File "/home/ace/flask_api/app/libs/error_code.py", line 59, in __init__
    super(APIException, self).__init__(msg, code, error_code)
NameError: name 'error_code' is not defined
2019-04-17 14:42:03 decorators.py[line:120] error(ERROR): Request(192.168.0.39): [POST] Args: /onecity/v1/register? Body: {}
2019-04-17 14:42:03 decorators.py[line:121] error(ERROR): name 'error_code' is not defined
Traceback (most recent call last):
  File "/home/ace/flask_api/app/onecity_v1/decorators.py", line 106, in wrapper
    return view(*args, **kwargs)
  File "/home/ace/flask_api/app/onecity_v1/decorators.py", line 52, in wrapper
    resp = view(*args, **kwargs)
  File "/home/ace/flask_api/app/onecity_v1/decorators.py", line 44, in wrapper
    return view(*args, **kwargs)
  File "/home/ace/flask_api/app/onecity_v1/api/register.py", line 19, in post
    return Success()
  File "/home/ace/flask_api/app/libs/error_code.py", line 59, in __init__
    super(APIException, self).__init__(msg, code=code, error_code=error_code)
NameError: name 'error_code' is not defined
2019-04-17 14:54:50 decorators.py[line:120] error(ERROR): Request(192.168.0.39): [POST] Args: /onecity/v1/register? Body: {}
2019-04-17 14:54:50 decorators.py[line:121] error(ERROR): 'Success' object has no attribute 'data'
Traceback (most recent call last):
  File "/home/ace/flask_api/app/onecity_v1/decorators.py", line 106, in wrapper
    return view(*args, **kwargs)
  File "/home/ace/flask_api/app/onecity_v1/decorators.py", line 52, in wrapper
    resp = view(*args, **kwargs)
  File "/home/ace/flask_api/app/onecity_v1/decorators.py", line 44, in wrapper
    return view(*args, **kwargs)
  File "/home/ace/flask_api/app/onecity_v1/api/register.py", line 19, in post
    return Success('用户创建成功')
  File "/home/ace/flask_api/app/libs/error_code.py", line 58, in __init__
    print(self.data)
AttributeError: 'Success' object has no attribute 'data'
2019-04-17 14:55:44 decorators.py[line:120] error(ERROR): Request(192.168.0.39): [POST] Args: /onecity/v1/register? Body: {}
2019-04-17 14:55:44 decorators.py[line:121] error(ERROR): 'Success' object has no attribute 'data'
Traceback (most recent call last):
  File "/home/ace/flask_api/app/onecity_v1/decorators.py", line 106, in wrapper
    return view(*args, **kwargs)
  File "/home/ace/flask_api/app/onecity_v1/decorators.py", line 52, in wrapper
    resp = view(*args, **kwargs)
  File "/home/ace/flask_api/app/onecity_v1/decorators.py", line 44, in wrapper
    return view(*args, **kwargs)
  File "/home/ace/flask_api/app/onecity_v1/api/register.py", line 19, in post
    return Success('用户创建成功')
  File "/home/ace/flask_api/app/libs/error_code.py", line 59, in __init__
    print(self.data)
AttributeError: 'Success' object has no attribute 'data'
2019-04-17 14:56:07 decorators.py[line:120] error(ERROR): Request(192.168.0.39): [POST] Args: /onecity/v1/register? Body: {}
2019-04-17 14:56:07 decorators.py[line:121] error(ERROR): 'Success' object has no attribute 'data'
Traceback (most recent call last):
  File "/home/ace/flask_api/app/onecity_v1/decorators.py", line 106, in wrapper
    return view(*args, **kwargs)
  File "/home/ace/flask_api/app/onecity_v1/decorators.py", line 52, in wrapper
    resp = view(*args, **kwargs)
  File "/home/ace/flask_api/app/onecity_v1/decorators.py", line 44, in wrapper
    return view(*args, **kwargs)
  File "/home/ace/flask_api/app/onecity_v1/api/register.py", line 19, in post
    raise Success('用户创建成功')
  File "/home/ace/flask_api/app/libs/error_code.py", line 58, in __init__
    print(self.data)
AttributeError: 'Success' object has no attribute 'data'
2019-04-17 14:56:08 decorators.py[line:120] error(ERROR): Request(192.168.0.39): [POST] Args: /onecity/v1/register? Body: {}
2019-04-17 14:56:08 decorators.py[line:121] error(ERROR): 'Success' object has no attribute 'data'
Traceback (most recent call last):
  File "/home/ace/flask_api/app/onecity_v1/decorators.py", line 106, in wrapper
    return view(*args, **kwargs)
  File "/home/ace/flask_api/app/onecity_v1/decorators.py", line 52, in wrapper
    resp = view(*args, **kwargs)
  File "/home/ace/flask_api/app/onecity_v1/decorators.py", line 44, in wrapper
    return view(*args, **kwargs)
  File "/home/ace/flask_api/app/onecity_v1/api/register.py", line 19, in post
    raise Success('用户创建成功')
  File "/home/ace/flask_api/app/libs/error_code.py", line 58, in __init__
    print(self.data)
AttributeError: 'Success' object has no attribute 'data'
2019-04-17 14:56:54 decorators.py[line:120] error(ERROR): Request(192.168.0.39): [POST] Args: /onecity/v1/register? Body: {}
2019-04-17 14:56:54 decorators.py[line:121] error(ERROR): 'Success' object has no attribute 'data'
Traceback (most recent call last):
  File "/home/ace/flask_api/app/onecity_v1/decorators.py", line 106, in wrapper
    return view(*args, **kwargs)
  File "/home/ace/flask_api/app/onecity_v1/decorators.py", line 52, in wrapper
    resp = view(*args, **kwargs)
  File "/home/ace/flask_api/app/onecity_v1/decorators.py", line 44, in wrapper
    return view(*args, **kwargs)
  File "/home/ace/flask_api/app/onecity_v1/api/register.py", line 19, in post
    return Success('用户创建成功')
  File "/home/ace/flask_api/app/libs/error_code.py", line 58, in __init__
    print(self.data)
AttributeError: 'Success' object has no attribute 'data'
2019-04-17 14:57:17 decorators.py[line:120] error(ERROR): Request(192.168.0.39): [POST] Args: /onecity/v1/register? Body: {}
2019-04-17 14:57:17 decorators.py[line:121] error(ERROR): 'Success' object has no attribute 'data'
Traceback (most recent call last):
  File "/home/ace/flask_api/app/onecity_v1/decorators.py", line 106, in wrapper
    return view(*args, **kwargs)
  File "/home/ace/flask_api/app/onecity_v1/decorators.py", line 52, in wrapper
    resp = view(*args, **kwargs)
  File "/home/ace/flask_api/app/onecity_v1/decorators.py", line 44, in wrapper
    return view(*args, **kwargs)
  File "/home/ace/flask_api/app/onecity_v1/api/register.py", line 19, in post
    return Success('用户创建成功')
  File "/home/ace/flask_api/app/libs/error_code.py", line 58, in __init__
    print(self.data)
AttributeError: 'Success' object has no attribute 'data'
2019-04-17 14:57:27 decorators.py[line:120] error(ERROR): Request(192.168.0.39): [POST] Args: /onecity/v1/register? Body: {}
2019-04-17 14:57:27 decorators.py[line:121] error(ERROR): 'Success' object has no attribute 'data'
Traceback (most recent call last):
  File "/home/ace/flask_api/app/onecity_v1/decorators.py", line 106, in wrapper
    return view(*args, **kwargs)
  File "/home/ace/flask_api/app/onecity_v1/decorators.py", line 52, in wrapper
    resp = view(*args, **kwargs)
  File "/home/ace/flask_api/app/onecity_v1/decorators.py", line 44, in wrapper
    return view(*args, **kwargs)
  File "/home/ace/flask_api/app/onecity_v1/api/register.py", line 19, in post
    return Success('用户创建成功')
  File "/home/ace/flask_api/app/libs/error_code.py", line 58, in __init__
    print(self.data)
AttributeError: 'Success' object has no attribute 'data'
2019-04-17 14:57:53 decorators.py[line:120] error(ERROR): Request(192.168.0.39): [POST] Args: /onecity/v1/register? Body: {}
2019-04-17 14:57:53 decorators.py[line:121] error(ERROR): 'Success' object has no attribute 'data'
Traceback (most recent call last):
  File "/home/ace/flask_api/app/onecity_v1/decorators.py", line 106, in wrapper
    return view(*args, **kwargs)
  File "/home/ace/flask_api/app/onecity_v1/decorators.py", line 52, in wrapper
    resp = view(*args, **kwargs)
  File "/home/ace/flask_api/app/onecity_v1/decorators.py", line 44, in wrapper
    return view(*args, **kwargs)
  File "/home/ace/flask_api/app/onecity_v1/api/register.py", line 20, in post
    return Success('用户创建成功')
  File "/home/ace/flask_api/app/libs/error_code.py", line 58, in __init__
    print(self.data)
AttributeError: 'Success' object has no attribute 'data'
2019-04-17 14:58:34 decorators.py[line:120] error(ERROR): Request(192.168.0.39): [POST] Args: /onecity/v1/register? Body: {}
2019-04-17 14:58:34 decorators.py[line:121] error(ERROR): 'Success' object has no attribute 'data'
Traceback (most recent call last):
  File "/home/ace/flask_api/app/onecity_v1/decorators.py", line 106, in wrapper
    return view(*args, **kwargs)
  File "/home/ace/flask_api/app/onecity_v1/decorators.py", line 52, in wrapper
    resp = view(*args, **kwargs)
  File "/home/ace/flask_api/app/onecity_v1/decorators.py", line 44, in wrapper
    return view(*args, **kwargs)
  File "/home/ace/flask_api/app/onecity_v1/api/register.py", line 20, in post
    return Success('用户创建成功')
  File "/home/ace/flask_api/app/libs/error_code.py", line 58, in __init__
    print(self.data)
AttributeError: 'Success' object has no attribute 'data'
2019-04-17 16:18:53 decorators.py[line:117] error(ERROR): Request(192.168.0.39): [POST] Args: /onecity/v1/register? Body: {}
2019-04-17 16:18:53 decorators.py[line:118] error(ERROR): name 'code' is not defined
Traceback (most recent call last):
  File "/home/ace/flask_api/app/onecity_v1/decorators.py", line 106, in wrapper
    return view(*args, **kwargs)
  File "/home/ace/flask_api/app/onecity_v1/decorators.py", line 52, in wrapper
    resp = view(*args, **kwargs)
  File "/home/ace/flask_api/app/onecity_v1/decorators.py", line 44, in wrapper
    return view(*args, **kwargs)
  File "/home/ace/flask_api/app/onecity_v1/api/register.py", line 20, in post
    return Success('用户创建成功')
  File "/home/ace/flask_api/app/libs/error_code.py", line 57, in __init__
    if code:
NameError: name 'code' is not defined
2019-04-17 16:18:57 decorators.py[line:117] error(ERROR): Request(192.168.0.39): [POST] Args: /onecity/v1/register? Body: {}
2019-04-17 16:18:57 decorators.py[line:118] error(ERROR): name 'code' is not defined
Traceback (most recent call last):
  File "/home/ace/flask_api/app/onecity_v1/decorators.py", line 106, in wrapper
    return view(*args, **kwargs)
  File "/home/ace/flask_api/app/onecity_v1/decorators.py", line 52, in wrapper
    resp = view(*args, **kwargs)
  File "/home/ace/flask_api/app/onecity_v1/decorators.py", line 44, in wrapper
    return view(*args, **kwargs)
  File "/home/ace/flask_api/app/onecity_v1/api/register.py", line 20, in post
    return Success('用户创建成功')
  File "/home/ace/flask_api/app/libs/error_code.py", line 57, in __init__
    if code:
NameError: name 'code' is not defined
2019-04-17 17:29:43 decorators.py[line:119] error(ERROR): Request(192.168.0.39): [POST] Args: /onecity/v1/register? Body: {}
2019-04-17 17:29:43 decorators.py[line:120] error(ERROR): (pymysql.err.InternalError) (1054, "Unknown column 'user.password' in 'field list'")
[SQL: SELECT user.create_time AS user_create_time, user.password AS user_password, user.update_time AS user_update_time, user.delete_time AS user_delete_time, user.id AS user_id, user.nickname AS user_nickname, user.super AS user_super, user.active AS user_active, user.group_id AS user_group_id 
FROM user 
WHERE user.nickname = %(nickname_1)s 
 LIMIT %(param_1)s]
[parameters: {'nickname_1': 'string', 'param_1': 1}]
(Background on this error at: http://sqlalche.me/e/2j85)
Traceback (most recent call last):
  File "/home/ace/.local/share/virtualenvs/flask_api-NEe1upaw/lib/python3.6/site-packages/sqlalchemy/engine/base.py", line 1244, in _execute_context
    cursor, statement, parameters, context
  File "/home/ace/.local/share/virtualenvs/flask_api-NEe1upaw/lib/python3.6/site-packages/sqlalchemy/engine/default.py", line 552, in do_execute
    cursor.execute(statement, parameters)
  File "/home/ace/.local/share/virtualenvs/flask_api-NEe1upaw/lib/python3.6/site-packages/pymysql/cursors.py", line 170, in execute
    result = self._query(query)
  File "/home/ace/.local/share/virtualenvs/flask_api-NEe1upaw/lib/python3.6/site-packages/pymysql/cursors.py", line 328, in _query
    conn.query(q)
  File "/home/ace/.local/share/virtualenvs/flask_api-NEe1upaw/lib/python3.6/site-packages/pymysql/connections.py", line 517, in query
    self._affected_rows = self._read_query_result(unbuffered=unbuffered)
  File "/home/ace/.local/share/virtualenvs/flask_api-NEe1upaw/lib/python3.6/site-packages/pymysql/connections.py", line 732, in _read_query_result
    result.read()
  File "/home/ace/.local/share/virtualenvs/flask_api-NEe1upaw/lib/python3.6/site-packages/pymysql/connections.py", line 1075, in read
    first_packet = self.connection._read_packet()
  File "/home/ace/.local/share/virtualenvs/flask_api-NEe1upaw/lib/python3.6/site-packages/pymysql/connections.py", line 684, in _read_packet
    packet.check_error()
  File "/home/ace/.local/share/virtualenvs/flask_api-NEe1upaw/lib/python3.6/site-packages/pymysql/protocol.py", line 220, in check_error
    err.raise_mysql_exception(self._data)
  File "/home/ace/.local/share/virtualenvs/flask_api-NEe1upaw/lib/python3.6/site-packages/pymysql/err.py", line 109, in raise_mysql_exception
    raise errorclass(errno, errval)
pymysql.err.InternalError: (1054, "Unknown column 'user.password' in 'field list'")

The above exception was the direct cause of the following exception:

Traceback (most recent call last):
  File "/home/ace/flask_api/app/onecity_v1/decorators.py", line 106, in wrapper
    return view(*args, **kwargs)
  File "/home/ace/flask_api/app/onecity_v1/decorators.py", line 52, in wrapper
    resp = view(*args, **kwargs)
  File "/home/ace/flask_api/app/onecity_v1/decorators.py", line 44, in wrapper
    return view(*args, **kwargs)
  File "/home/ace/flask_api/app/onecity_v1/api/register.py", line 18, in post
    data = user.post_user(g.json)
  File "/home/ace/flask_api/app/services/user.py", line 11, in post_user
    user = User.find_user(nickname=nickname)
  File "/home/ace/flask_api/app/models/user.py", line 46, in find_user
    return User.query.filter_by(**kwargs).first()
  File "/home/ace/.local/share/virtualenvs/flask_api-NEe1upaw/lib/python3.6/site-packages/sqlalchemy/orm/query.py", line 3215, in first
    ret = list(self[0:1])
  File "/home/ace/.local/share/virtualenvs/flask_api-NEe1upaw/lib/python3.6/site-packages/sqlalchemy/orm/query.py", line 3007, in __getitem__
    return list(res)
  File "/home/ace/.local/share/virtualenvs/flask_api-NEe1upaw/lib/python3.6/site-packages/sqlalchemy/orm/query.py", line 3317, in __iter__
    return self._execute_and_instances(context)
  File "/home/ace/.local/share/virtualenvs/flask_api-NEe1upaw/lib/python3.6/site-packages/sqlalchemy/orm/query.py", line 3342, in _execute_and_instances
    result = conn.execute(querycontext.statement, self._params)
  File "/home/ace/.local/share/virtualenvs/flask_api-NEe1upaw/lib/python3.6/site-packages/sqlalchemy/engine/base.py", line 988, in execute
    return meth(self, multiparams, params)
  File "/home/ace/.local/share/virtualenvs/flask_api-NEe1upaw/lib/python3.6/site-packages/sqlalchemy/sql/elements.py", line 287, in _execute_on_connection
    return connection._execute_clauseelement(self, multiparams, params)
  File "/home/ace/.local/share/virtualenvs/flask_api-NEe1upaw/lib/python3.6/site-packages/sqlalchemy/engine/base.py", line 1107, in _execute_clauseelement
    distilled_params,
  File "/home/ace/.local/share/virtualenvs/flask_api-NEe1upaw/lib/python3.6/site-packages/sqlalchemy/engine/base.py", line 1248, in _execute_context
    e, statement, parameters, cursor, context
  File "/home/ace/.local/share/virtualenvs/flask_api-NEe1upaw/lib/python3.6/site-packages/sqlalchemy/engine/base.py", line 1466, in _handle_dbapi_exception
    util.raise_from_cause(sqlalchemy_exception, exc_info)
  File "/home/ace/.local/share/virtualenvs/flask_api-NEe1upaw/lib/python3.6/site-packages/sqlalchemy/util/compat.py", line 383, in raise_from_cause
    reraise(type(exception), exception, tb=exc_tb, cause=cause)
  File "/home/ace/.local/share/virtualenvs/flask_api-NEe1upaw/lib/python3.6/site-packages/sqlalchemy/util/compat.py", line 128, in reraise
    raise value.with_traceback(tb)
  File "/home/ace/.local/share/virtualenvs/flask_api-NEe1upaw/lib/python3.6/site-packages/sqlalchemy/engine/base.py", line 1244, in _execute_context
    cursor, statement, parameters, context
  File "/home/ace/.local/share/virtualenvs/flask_api-NEe1upaw/lib/python3.6/site-packages/sqlalchemy/engine/default.py", line 552, in do_execute
    cursor.execute(statement, parameters)
  File "/home/ace/.local/share/virtualenvs/flask_api-NEe1upaw/lib/python3.6/site-packages/pymysql/cursors.py", line 170, in execute
    result = self._query(query)
  File "/home/ace/.local/share/virtualenvs/flask_api-NEe1upaw/lib/python3.6/site-packages/pymysql/cursors.py", line 328, in _query
    conn.query(q)
  File "/home/ace/.local/share/virtualenvs/flask_api-NEe1upaw/lib/python3.6/site-packages/pymysql/connections.py", line 517, in query
    self._affected_rows = self._read_query_result(unbuffered=unbuffered)
  File "/home/ace/.local/share/virtualenvs/flask_api-NEe1upaw/lib/python3.6/site-packages/pymysql/connections.py", line 732, in _read_query_result
    result.read()
  File "/home/ace/.local/share/virtualenvs/flask_api-NEe1upaw/lib/python3.6/site-packages/pymysql/connections.py", line 1075, in read
    first_packet = self.connection._read_packet()
  File "/home/ace/.local/share/virtualenvs/flask_api-NEe1upaw/lib/python3.6/site-packages/pymysql/connections.py", line 684, in _read_packet
    packet.check_error()
  File "/home/ace/.local/share/virtualenvs/flask_api-NEe1upaw/lib/python3.6/site-packages/pymysql/protocol.py", line 220, in check_error
    err.raise_mysql_exception(self._data)
  File "/home/ace/.local/share/virtualenvs/flask_api-NEe1upaw/lib/python3.6/site-packages/pymysql/err.py", line 109, in raise_mysql_exception
    raise errorclass(errno, errval)
sqlalchemy.exc.InternalError: (pymysql.err.InternalError) (1054, "Unknown column 'user.password' in 'field list'")
[SQL: SELECT user.create_time AS user_create_time, user.password AS user_password, user.update_time AS user_update_time, user.delete_time AS user_delete_time, user.id AS user_id, user.nickname AS user_nickname, user.super AS user_super, user.active AS user_active, user.group_id AS user_group_id 
FROM user 
WHERE user.nickname = %(nickname_1)s 
 LIMIT %(param_1)s]
[parameters: {'nickname_1': 'string', 'param_1': 1}]
(Background on this error at: http://sqlalche.me/e/2j85)
2019-04-17 17:30:02 decorators.py[line:119] error(ERROR): Request(192.168.0.39): [POST] Args: /onecity/v1/register? Body: {}
2019-04-17 17:30:02 decorators.py[line:120] error(ERROR): (pymysql.err.InternalError) (1054, "Unknown column 'user.password' in 'field list'")
[SQL: SELECT user.create_time AS user_create_time, user.password AS user_password, user.update_time AS user_update_time, user.delete_time AS user_delete_time, user.id AS user_id, user.nickname AS user_nickname, user.super AS user_super, user.active AS user_active, user.group_id AS user_group_id 
FROM user 
WHERE user.nickname = %(nickname_1)s 
 LIMIT %(param_1)s]
[parameters: {'nickname_1': 'string', 'param_1': 1}]
(Background on this error at: http://sqlalche.me/e/2j85)
Traceback (most recent call last):
  File "/home/ace/.local/share/virtualenvs/flask_api-NEe1upaw/lib/python3.6/site-packages/sqlalchemy/engine/base.py", line 1244, in _execute_context
    cursor, statement, parameters, context
  File "/home/ace/.local/share/virtualenvs/flask_api-NEe1upaw/lib/python3.6/site-packages/sqlalchemy/engine/default.py", line 552, in do_execute
    cursor.execute(statement, parameters)
  File "/home/ace/.local/share/virtualenvs/flask_api-NEe1upaw/lib/python3.6/site-packages/pymysql/cursors.py", line 170, in execute
    result = self._query(query)
  File "/home/ace/.local/share/virtualenvs/flask_api-NEe1upaw/lib/python3.6/site-packages/pymysql/cursors.py", line 328, in _query
    conn.query(q)
  File "/home/ace/.local/share/virtualenvs/flask_api-NEe1upaw/lib/python3.6/site-packages/pymysql/connections.py", line 517, in query
    self._affected_rows = self._read_query_result(unbuffered=unbuffered)
  File "/home/ace/.local/share/virtualenvs/flask_api-NEe1upaw/lib/python3.6/site-packages/pymysql/connections.py", line 732, in _read_query_result
    result.read()
  File "/home/ace/.local/share/virtualenvs/flask_api-NEe1upaw/lib/python3.6/site-packages/pymysql/connections.py", line 1075, in read
    first_packet = self.connection._read_packet()
  File "/home/ace/.local/share/virtualenvs/flask_api-NEe1upaw/lib/python3.6/site-packages/pymysql/connections.py", line 684, in _read_packet
    packet.check_error()
  File "/home/ace/.local/share/virtualenvs/flask_api-NEe1upaw/lib/python3.6/site-packages/pymysql/protocol.py", line 220, in check_error
    err.raise_mysql_exception(self._data)
  File "/home/ace/.local/share/virtualenvs/flask_api-NEe1upaw/lib/python3.6/site-packages/pymysql/err.py", line 109, in raise_mysql_exception
    raise errorclass(errno, errval)
pymysql.err.InternalError: (1054, "Unknown column 'user.password' in 'field list'")

The above exception was the direct cause of the following exception:

Traceback (most recent call last):
  File "/home/ace/flask_api/app/onecity_v1/decorators.py", line 106, in wrapper
    return view(*args, **kwargs)
  File "/home/ace/flask_api/app/onecity_v1/decorators.py", line 52, in wrapper
    resp = view(*args, **kwargs)
  File "/home/ace/flask_api/app/onecity_v1/decorators.py", line 44, in wrapper
    return view(*args, **kwargs)
  File "/home/ace/flask_api/app/onecity_v1/api/register.py", line 18, in post
    data = user.post_user(g.json)
  File "/home/ace/flask_api/app/services/user.py", line 11, in post_user
    user = User.find_user(nickname=nickname)
  File "/home/ace/flask_api/app/models/user.py", line 46, in find_user
    return User.query.filter_by(**kwargs).first()
  File "/home/ace/.local/share/virtualenvs/flask_api-NEe1upaw/lib/python3.6/site-packages/sqlalchemy/orm/query.py", line 3215, in first
    ret = list(self[0:1])
  File "/home/ace/.local/share/virtualenvs/flask_api-NEe1upaw/lib/python3.6/site-packages/sqlalchemy/orm/query.py", line 3007, in __getitem__
    return list(res)
  File "/home/ace/.local/share/virtualenvs/flask_api-NEe1upaw/lib/python3.6/site-packages/sqlalchemy/orm/query.py", line 3317, in __iter__
    return self._execute_and_instances(context)
  File "/home/ace/.local/share/virtualenvs/flask_api-NEe1upaw/lib/python3.6/site-packages/sqlalchemy/orm/query.py", line 3342, in _execute_and_instances
    result = conn.execute(querycontext.statement, self._params)
  File "/home/ace/.local/share/virtualenvs/flask_api-NEe1upaw/lib/python3.6/site-packages/sqlalchemy/engine/base.py", line 988, in execute
    return meth(self, multiparams, params)
  File "/home/ace/.local/share/virtualenvs/flask_api-NEe1upaw/lib/python3.6/site-packages/sqlalchemy/sql/elements.py", line 287, in _execute_on_connection
    return connection._execute_clauseelement(self, multiparams, params)
  File "/home/ace/.local/share/virtualenvs/flask_api-NEe1upaw/lib/python3.6/site-packages/sqlalchemy/engine/base.py", line 1107, in _execute_clauseelement
    distilled_params,
  File "/home/ace/.local/share/virtualenvs/flask_api-NEe1upaw/lib/python3.6/site-packages/sqlalchemy/engine/base.py", line 1248, in _execute_context
    e, statement, parameters, cursor, context
  File "/home/ace/.local/share/virtualenvs/flask_api-NEe1upaw/lib/python3.6/site-packages/sqlalchemy/engine/base.py", line 1466, in _handle_dbapi_exception
    util.raise_from_cause(sqlalchemy_exception, exc_info)
  File "/home/ace/.local/share/virtualenvs/flask_api-NEe1upaw/lib/python3.6/site-packages/sqlalchemy/util/compat.py", line 383, in raise_from_cause
    reraise(type(exception), exception, tb=exc_tb, cause=cause)
  File "/home/ace/.local/share/virtualenvs/flask_api-NEe1upaw/lib/python3.6/site-packages/sqlalchemy/util/compat.py", line 128, in reraise
    raise value.with_traceback(tb)
  File "/home/ace/.local/share/virtualenvs/flask_api-NEe1upaw/lib/python3.6/site-packages/sqlalchemy/engine/base.py", line 1244, in _execute_context
    cursor, statement, parameters, context
  File "/home/ace/.local/share/virtualenvs/flask_api-NEe1upaw/lib/python3.6/site-packages/sqlalchemy/engine/default.py", line 552, in do_execute
    cursor.execute(statement, parameters)
  File "/home/ace/.local/share/virtualenvs/flask_api-NEe1upaw/lib/python3.6/site-packages/pymysql/cursors.py", line 170, in execute
    result = self._query(query)
  File "/home/ace/.local/share/virtualenvs/flask_api-NEe1upaw/lib/python3.6/site-packages/pymysql/cursors.py", line 328, in _query
    conn.query(q)
  File "/home/ace/.local/share/virtualenvs/flask_api-NEe1upaw/lib/python3.6/site-packages/pymysql/connections.py", line 517, in query
    self._affected_rows = self._read_query_result(unbuffered=unbuffered)
  File "/home/ace/.local/share/virtualenvs/flask_api-NEe1upaw/lib/python3.6/site-packages/pymysql/connections.py", line 732, in _read_query_result
    result.read()
  File "/home/ace/.local/share/virtualenvs/flask_api-NEe1upaw/lib/python3.6/site-packages/pymysql/connections.py", line 1075, in read
    first_packet = self.connection._read_packet()
  File "/home/ace/.local/share/virtualenvs/flask_api-NEe1upaw/lib/python3.6/site-packages/pymysql/connections.py", line 684, in _read_packet
    packet.check_error()
  File "/home/ace/.local/share/virtualenvs/flask_api-NEe1upaw/lib/python3.6/site-packages/pymysql/protocol.py", line 220, in check_error
    err.raise_mysql_exception(self._data)
  File "/home/ace/.local/share/virtualenvs/flask_api-NEe1upaw/lib/python3.6/site-packages/pymysql/err.py", line 109, in raise_mysql_exception
    raise errorclass(errno, errval)
sqlalchemy.exc.InternalError: (pymysql.err.InternalError) (1054, "Unknown column 'user.password' in 'field list'")
[SQL: SELECT user.create_time AS user_create_time, user.password AS user_password, user.update_time AS user_update_time, user.delete_time AS user_delete_time, user.id AS user_id, user.nickname AS user_nickname, user.super AS user_super, user.active AS user_active, user.group_id AS user_group_id 
FROM user 
WHERE user.nickname = %(nickname_1)s 
 LIMIT %(param_1)s]
[parameters: {'nickname_1': 'string', 'param_1': 1}]
(Background on this error at: http://sqlalche.me/e/2j85)
2019-04-17 17:31:07 decorators.py[line:119] error(ERROR): Request(192.168.0.39): [POST] Args: /onecity/v1/register? Body: {}
2019-04-17 17:31:07 decorators.py[line:120] error(ERROR): (pymysql.err.InternalError) (1054, "Unknown column 'user.password' in 'field list'")
[SQL: SELECT user.create_time AS user_create_time, user.password AS user_password, user.update_time AS user_update_time, user.delete_time AS user_delete_time, user.id AS user_id, user.nickname AS user_nickname, user.super AS user_super, user.active AS user_active, user.group_id AS user_group_id 
FROM user 
WHERE user.nickname = %(nickname_1)s 
 LIMIT %(param_1)s]
[parameters: {'nickname_1': 'string', 'param_1': 1}]
(Background on this error at: http://sqlalche.me/e/2j85)
Traceback (most recent call last):
  File "/home/ace/.local/share/virtualenvs/flask_api-NEe1upaw/lib/python3.6/site-packages/sqlalchemy/engine/base.py", line 1244, in _execute_context
    cursor, statement, parameters, context
  File "/home/ace/.local/share/virtualenvs/flask_api-NEe1upaw/lib/python3.6/site-packages/sqlalchemy/engine/default.py", line 552, in do_execute
    cursor.execute(statement, parameters)
  File "/home/ace/.local/share/virtualenvs/flask_api-NEe1upaw/lib/python3.6/site-packages/pymysql/cursors.py", line 170, in execute
    result = self._query(query)
  File "/home/ace/.local/share/virtualenvs/flask_api-NEe1upaw/lib/python3.6/site-packages/pymysql/cursors.py", line 328, in _query
    conn.query(q)
  File "/home/ace/.local/share/virtualenvs/flask_api-NEe1upaw/lib/python3.6/site-packages/pymysql/connections.py", line 517, in query
    self._affected_rows = self._read_query_result(unbuffered=unbuffered)
  File "/home/ace/.local/share/virtualenvs/flask_api-NEe1upaw/lib/python3.6/site-packages/pymysql/connections.py", line 732, in _read_query_result
    result.read()
  File "/home/ace/.local/share/virtualenvs/flask_api-NEe1upaw/lib/python3.6/site-packages/pymysql/connections.py", line 1075, in read
    first_packet = self.connection._read_packet()
  File "/home/ace/.local/share/virtualenvs/flask_api-NEe1upaw/lib/python3.6/site-packages/pymysql/connections.py", line 684, in _read_packet
    packet.check_error()
  File "/home/ace/.local/share/virtualenvs/flask_api-NEe1upaw/lib/python3.6/site-packages/pymysql/protocol.py", line 220, in check_error
    err.raise_mysql_exception(self._data)
  File "/home/ace/.local/share/virtualenvs/flask_api-NEe1upaw/lib/python3.6/site-packages/pymysql/err.py", line 109, in raise_mysql_exception
    raise errorclass(errno, errval)
pymysql.err.InternalError: (1054, "Unknown column 'user.password' in 'field list'")

The above exception was the direct cause of the following exception:

Traceback (most recent call last):
  File "/home/ace/flask_api/app/onecity_v1/decorators.py", line 106, in wrapper
    return view(*args, **kwargs)
  File "/home/ace/flask_api/app/onecity_v1/decorators.py", line 52, in wrapper
    resp = view(*args, **kwargs)
  File "/home/ace/flask_api/app/onecity_v1/decorators.py", line 44, in wrapper
    return view(*args, **kwargs)
  File "/home/ace/flask_api/app/onecity_v1/api/register.py", line 18, in post
    data = user.post_user(g.json)
  File "/home/ace/flask_api/app/services/user.py", line 11, in post_user
    user = User.find_user(nickname=nickname)
  File "/home/ace/flask_api/app/models/user.py", line 46, in find_user
    return User.query.filter_by(**kwargs).first()
  File "/home/ace/.local/share/virtualenvs/flask_api-NEe1upaw/lib/python3.6/site-packages/sqlalchemy/orm/query.py", line 3215, in first
    ret = list(self[0:1])
  File "/home/ace/.local/share/virtualenvs/flask_api-NEe1upaw/lib/python3.6/site-packages/sqlalchemy/orm/query.py", line 3007, in __getitem__
    return list(res)
  File "/home/ace/.local/share/virtualenvs/flask_api-NEe1upaw/lib/python3.6/site-packages/sqlalchemy/orm/query.py", line 3317, in __iter__
    return self._execute_and_instances(context)
  File "/home/ace/.local/share/virtualenvs/flask_api-NEe1upaw/lib/python3.6/site-packages/sqlalchemy/orm/query.py", line 3342, in _execute_and_instances
    result = conn.execute(querycontext.statement, self._params)
  File "/home/ace/.local/share/virtualenvs/flask_api-NEe1upaw/lib/python3.6/site-packages/sqlalchemy/engine/base.py", line 988, in execute
    return meth(self, multiparams, params)
  File "/home/ace/.local/share/virtualenvs/flask_api-NEe1upaw/lib/python3.6/site-packages/sqlalchemy/sql/elements.py", line 287, in _execute_on_connection
    return connection._execute_clauseelement(self, multiparams, params)
  File "/home/ace/.local/share/virtualenvs/flask_api-NEe1upaw/lib/python3.6/site-packages/sqlalchemy/engine/base.py", line 1107, in _execute_clauseelement
    distilled_params,
  File "/home/ace/.local/share/virtualenvs/flask_api-NEe1upaw/lib/python3.6/site-packages/sqlalchemy/engine/base.py", line 1248, in _execute_context
    e, statement, parameters, cursor, context
  File "/home/ace/.local/share/virtualenvs/flask_api-NEe1upaw/lib/python3.6/site-packages/sqlalchemy/engine/base.py", line 1466, in _handle_dbapi_exception
    util.raise_from_cause(sqlalchemy_exception, exc_info)
  File "/home/ace/.local/share/virtualenvs/flask_api-NEe1upaw/lib/python3.6/site-packages/sqlalchemy/util/compat.py", line 383, in raise_from_cause
    reraise(type(exception), exception, tb=exc_tb, cause=cause)
  File "/home/ace/.local/share/virtualenvs/flask_api-NEe1upaw/lib/python3.6/site-packages/sqlalchemy/util/compat.py", line 128, in reraise
    raise value.with_traceback(tb)
  File "/home/ace/.local/share/virtualenvs/flask_api-NEe1upaw/lib/python3.6/site-packages/sqlalchemy/engine/base.py", line 1244, in _execute_context
    cursor, statement, parameters, context
  File "/home/ace/.local/share/virtualenvs/flask_api-NEe1upaw/lib/python3.6/site-packages/sqlalchemy/engine/default.py", line 552, in do_execute
    cursor.execute(statement, parameters)
  File "/home/ace/.local/share/virtualenvs/flask_api-NEe1upaw/lib/python3.6/site-packages/pymysql/cursors.py", line 170, in execute
    result = self._query(query)
  File "/home/ace/.local/share/virtualenvs/flask_api-NEe1upaw/lib/python3.6/site-packages/pymysql/cursors.py", line 328, in _query
    conn.query(q)
  File "/home/ace/.local/share/virtualenvs/flask_api-NEe1upaw/lib/python3.6/site-packages/pymysql/connections.py", line 517, in query
    self._affected_rows = self._read_query_result(unbuffered=unbuffered)
  File "/home/ace/.local/share/virtualenvs/flask_api-NEe1upaw/lib/python3.6/site-packages/pymysql/connections.py", line 732, in _read_query_result
    result.read()
  File "/home/ace/.local/share/virtualenvs/flask_api-NEe1upaw/lib/python3.6/site-packages/pymysql/connections.py", line 1075, in read
    first_packet = self.connection._read_packet()
  File "/home/ace/.local/share/virtualenvs/flask_api-NEe1upaw/lib/python3.6/site-packages/pymysql/connections.py", line 684, in _read_packet
    packet.check_error()
  File "/home/ace/.local/share/virtualenvs/flask_api-NEe1upaw/lib/python3.6/site-packages/pymysql/protocol.py", line 220, in check_error
    err.raise_mysql_exception(self._data)
  File "/home/ace/.local/share/virtualenvs/flask_api-NEe1upaw/lib/python3.6/site-packages/pymysql/err.py", line 109, in raise_mysql_exception
    raise errorclass(errno, errval)
sqlalchemy.exc.InternalError: (pymysql.err.InternalError) (1054, "Unknown column 'user.password' in 'field list'")
[SQL: SELECT user.create_time AS user_create_time, user.password AS user_password, user.update_time AS user_update_time, user.delete_time AS user_delete_time, user.id AS user_id, user.nickname AS user_nickname, user.super AS user_super, user.active AS user_active, user.group_id AS user_group_id 
FROM user 
WHERE user.nickname = %(nickname_1)s 
 LIMIT %(param_1)s]
[parameters: {'nickname_1': 'string', 'param_1': 1}]
(Background on this error at: http://sqlalche.me/e/2j85)
2019-04-17 17:31:16 decorators.py[line:119] error(ERROR): Request(192.168.0.39): [POST] Args: /onecity/v1/register? Body: {}
2019-04-17 17:31:16 decorators.py[line:120] error(ERROR): (pymysql.err.InternalError) (1054, "Unknown column 'user.password' in 'field list'")
[SQL: SELECT user.create_time AS user_create_time, user.password AS user_password, user.update_time AS user_update_time, user.delete_time AS user_delete_time, user.id AS user_id, user.nickname AS user_nickname, user.super AS user_super, user.active AS user_active, user.group_id AS user_group_id 
FROM user 
WHERE user.nickname = %(nickname_1)s 
 LIMIT %(param_1)s]
[parameters: {'nickname_1': 'string', 'param_1': 1}]
(Background on this error at: http://sqlalche.me/e/2j85)
Traceback (most recent call last):
  File "/home/ace/.local/share/virtualenvs/flask_api-NEe1upaw/lib/python3.6/site-packages/sqlalchemy/engine/base.py", line 1244, in _execute_context
    cursor, statement, parameters, context
  File "/home/ace/.local/share/virtualenvs/flask_api-NEe1upaw/lib/python3.6/site-packages/sqlalchemy/engine/default.py", line 552, in do_execute
    cursor.execute(statement, parameters)
  File "/home/ace/.local/share/virtualenvs/flask_api-NEe1upaw/lib/python3.6/site-packages/pymysql/cursors.py", line 170, in execute
    result = self._query(query)
  File "/home/ace/.local/share/virtualenvs/flask_api-NEe1upaw/lib/python3.6/site-packages/pymysql/cursors.py", line 328, in _query
    conn.query(q)
  File "/home/ace/.local/share/virtualenvs/flask_api-NEe1upaw/lib/python3.6/site-packages/pymysql/connections.py", line 517, in query
    self._affected_rows = self._read_query_result(unbuffered=unbuffered)
  File "/home/ace/.local/share/virtualenvs/flask_api-NEe1upaw/lib/python3.6/site-packages/pymysql/connections.py", line 732, in _read_query_result
    result.read()
  File "/home/ace/.local/share/virtualenvs/flask_api-NEe1upaw/lib/python3.6/site-packages/pymysql/connections.py", line 1075, in read
    first_packet = self.connection._read_packet()
  File "/home/ace/.local/share/virtualenvs/flask_api-NEe1upaw/lib/python3.6/site-packages/pymysql/connections.py", line 684, in _read_packet
    packet.check_error()
  File "/home/ace/.local/share/virtualenvs/flask_api-NEe1upaw/lib/python3.6/site-packages/pymysql/protocol.py", line 220, in check_error
    err.raise_mysql_exception(self._data)
  File "/home/ace/.local/share/virtualenvs/flask_api-NEe1upaw/lib/python3.6/site-packages/pymysql/err.py", line 109, in raise_mysql_exception
    raise errorclass(errno, errval)
pymysql.err.InternalError: (1054, "Unknown column 'user.password' in 'field list'")

The above exception was the direct cause of the following exception:

Traceback (most recent call last):
  File "/home/ace/flask_api/app/onecity_v1/decorators.py", line 106, in wrapper
    return view(*args, **kwargs)
  File "/home/ace/flask_api/app/onecity_v1/decorators.py", line 52, in wrapper
    resp = view(*args, **kwargs)
  File "/home/ace/flask_api/app/onecity_v1/decorators.py", line 44, in wrapper
    return view(*args, **kwargs)
  File "/home/ace/flask_api/app/onecity_v1/api/register.py", line 18, in post
    data = user.post_user(g.json)
  File "/home/ace/flask_api/app/services/user.py", line 11, in post_user
    user = User.find_user(nickname=nickname)
  File "/home/ace/flask_api/app/models/user.py", line 46, in find_user
    return User.query.filter_by(**kwargs).first()
  File "/home/ace/.local/share/virtualenvs/flask_api-NEe1upaw/lib/python3.6/site-packages/sqlalchemy/orm/query.py", line 3215, in first
    ret = list(self[0:1])
  File "/home/ace/.local/share/virtualenvs/flask_api-NEe1upaw/lib/python3.6/site-packages/sqlalchemy/orm/query.py", line 3007, in __getitem__
    return list(res)
  File "/home/ace/.local/share/virtualenvs/flask_api-NEe1upaw/lib/python3.6/site-packages/sqlalchemy/orm/query.py", line 3317, in __iter__
    return self._execute_and_instances(context)
  File "/home/ace/.local/share/virtualenvs/flask_api-NEe1upaw/lib/python3.6/site-packages/sqlalchemy/orm/query.py", line 3342, in _execute_and_instances
    result = conn.execute(querycontext.statement, self._params)
  File "/home/ace/.local/share/virtualenvs/flask_api-NEe1upaw/lib/python3.6/site-packages/sqlalchemy/engine/base.py", line 988, in execute
    return meth(self, multiparams, params)
  File "/home/ace/.local/share/virtualenvs/flask_api-NEe1upaw/lib/python3.6/site-packages/sqlalchemy/sql/elements.py", line 287, in _execute_on_connection
    return connection._execute_clauseelement(self, multiparams, params)
  File "/home/ace/.local/share/virtualenvs/flask_api-NEe1upaw/lib/python3.6/site-packages/sqlalchemy/engine/base.py", line 1107, in _execute_clauseelement
    distilled_params,
  File "/home/ace/.local/share/virtualenvs/flask_api-NEe1upaw/lib/python3.6/site-packages/sqlalchemy/engine/base.py", line 1248, in _execute_context
    e, statement, parameters, cursor, context
  File "/home/ace/.local/share/virtualenvs/flask_api-NEe1upaw/lib/python3.6/site-packages/sqlalchemy/engine/base.py", line 1466, in _handle_dbapi_exception
    util.raise_from_cause(sqlalchemy_exception, exc_info)
  File "/home/ace/.local/share/virtualenvs/flask_api-NEe1upaw/lib/python3.6/site-packages/sqlalchemy/util/compat.py", line 383, in raise_from_cause
    reraise(type(exception), exception, tb=exc_tb, cause=cause)
  File "/home/ace/.local/share/virtualenvs/flask_api-NEe1upaw/lib/python3.6/site-packages/sqlalchemy/util/compat.py", line 128, in reraise
    raise value.with_traceback(tb)
  File "/home/ace/.local/share/virtualenvs/flask_api-NEe1upaw/lib/python3.6/site-packages/sqlalchemy/engine/base.py", line 1244, in _execute_context
    cursor, statement, parameters, context
  File "/home/ace/.local/share/virtualenvs/flask_api-NEe1upaw/lib/python3.6/site-packages/sqlalchemy/engine/default.py", line 552, in do_execute
    cursor.execute(statement, parameters)
  File "/home/ace/.local/share/virtualenvs/flask_api-NEe1upaw/lib/python3.6/site-packages/pymysql/cursors.py", line 170, in execute
    result = self._query(query)
  File "/home/ace/.local/share/virtualenvs/flask_api-NEe1upaw/lib/python3.6/site-packages/pymysql/cursors.py", line 328, in _query
    conn.query(q)
  File "/home/ace/.local/share/virtualenvs/flask_api-NEe1upaw/lib/python3.6/site-packages/pymysql/connections.py", line 517, in query
    self._affected_rows = self._read_query_result(unbuffered=unbuffered)
  File "/home/ace/.local/share/virtualenvs/flask_api-NEe1upaw/lib/python3.6/site-packages/pymysql/connections.py", line 732, in _read_query_result
    result.read()
  File "/home/ace/.local/share/virtualenvs/flask_api-NEe1upaw/lib/python3.6/site-packages/pymysql/connections.py", line 1075, in read
    first_packet = self.connection._read_packet()
  File "/home/ace/.local/share/virtualenvs/flask_api-NEe1upaw/lib/python3.6/site-packages/pymysql/connections.py", line 684, in _read_packet
    packet.check_error()
  File "/home/ace/.local/share/virtualenvs/flask_api-NEe1upaw/lib/python3.6/site-packages/pymysql/protocol.py", line 220, in check_error
    err.raise_mysql_exception(self._data)
  File "/home/ace/.local/share/virtualenvs/flask_api-NEe1upaw/lib/python3.6/site-packages/pymysql/err.py", line 109, in raise_mysql_exception
    raise errorclass(errno, errval)
sqlalchemy.exc.InternalError: (pymysql.err.InternalError) (1054, "Unknown column 'user.password' in 'field list'")
[SQL: SELECT user.create_time AS user_create_time, user.password AS user_password, user.update_time AS user_update_time, user.delete_time AS user_delete_time, user.id AS user_id, user.nickname AS user_nickname, user.super AS user_super, user.active AS user_active, user.group_id AS user_group_id 
FROM user 
WHERE user.nickname = %(nickname_1)s 
 LIMIT %(param_1)s]
[parameters: {'nickname_1': 'string', 'param_1': 1}]
(Background on this error at: http://sqlalche.me/e/2j85)
2019-04-17 17:31:53 decorators.py[line:119] error(ERROR): Request(192.168.0.39): [POST] Args: /onecity/v1/register? Body: {}
2019-04-17 17:31:53 decorators.py[line:120] error(ERROR): (pymysql.err.InternalError) (1054, "Unknown column 'user.password' in 'field list'")
[SQL: SELECT user.create_time AS user_create_time, user.password AS user_password, user.update_time AS user_update_time, user.delete_time AS user_delete_time, user.id AS user_id, user.nickname AS user_nickname, user.super AS user_super, user.active AS user_active, user.group_id AS user_group_id 
FROM user 
WHERE user.nickname = %(nickname_1)s 
 LIMIT %(param_1)s]
[parameters: {'nickname_1': 'string', 'param_1': 1}]
(Background on this error at: http://sqlalche.me/e/2j85)
Traceback (most recent call last):
  File "/home/ace/.local/share/virtualenvs/flask_api-NEe1upaw/lib/python3.6/site-packages/sqlalchemy/engine/base.py", line 1244, in _execute_context
    cursor, statement, parameters, context
  File "/home/ace/.local/share/virtualenvs/flask_api-NEe1upaw/lib/python3.6/site-packages/sqlalchemy/engine/default.py", line 552, in do_execute
    cursor.execute(statement, parameters)
  File "/home/ace/.local/share/virtualenvs/flask_api-NEe1upaw/lib/python3.6/site-packages/pymysql/cursors.py", line 170, in execute
    result = self._query(query)
  File "/home/ace/.local/share/virtualenvs/flask_api-NEe1upaw/lib/python3.6/site-packages/pymysql/cursors.py", line 328, in _query
    conn.query(q)
  File "/home/ace/.local/share/virtualenvs/flask_api-NEe1upaw/lib/python3.6/site-packages/pymysql/connections.py", line 517, in query
    self._affected_rows = self._read_query_result(unbuffered=unbuffered)
  File "/home/ace/.local/share/virtualenvs/flask_api-NEe1upaw/lib/python3.6/site-packages/pymysql/connections.py", line 732, in _read_query_result
    result.read()
  File "/home/ace/.local/share/virtualenvs/flask_api-NEe1upaw/lib/python3.6/site-packages/pymysql/connections.py", line 1075, in read
    first_packet = self.connection._read_packet()
  File "/home/ace/.local/share/virtualenvs/flask_api-NEe1upaw/lib/python3.6/site-packages/pymysql/connections.py", line 684, in _read_packet
    packet.check_error()
  File "/home/ace/.local/share/virtualenvs/flask_api-NEe1upaw/lib/python3.6/site-packages/pymysql/protocol.py", line 220, in check_error
    err.raise_mysql_exception(self._data)
  File "/home/ace/.local/share/virtualenvs/flask_api-NEe1upaw/lib/python3.6/site-packages/pymysql/err.py", line 109, in raise_mysql_exception
    raise errorclass(errno, errval)
pymysql.err.InternalError: (1054, "Unknown column 'user.password' in 'field list'")

The above exception was the direct cause of the following exception:

Traceback (most recent call last):
  File "/home/ace/flask_api/app/onecity_v1/decorators.py", line 106, in wrapper
    return view(*args, **kwargs)
  File "/home/ace/flask_api/app/onecity_v1/decorators.py", line 52, in wrapper
    resp = view(*args, **kwargs)
  File "/home/ace/flask_api/app/onecity_v1/decorators.py", line 44, in wrapper
    return view(*args, **kwargs)
  File "/home/ace/flask_api/app/onecity_v1/api/register.py", line 18, in post
    data = user.post_user(g.json)
  File "/home/ace/flask_api/app/services/user.py", line 12, in post_user
    user = User.find_user(nickname=nickname)
  File "/home/ace/flask_api/app/models/user.py", line 46, in find_user
    return User.query.filter_by(**kwargs).first()
  File "/home/ace/.local/share/virtualenvs/flask_api-NEe1upaw/lib/python3.6/site-packages/sqlalchemy/orm/query.py", line 3215, in first
    ret = list(self[0:1])
  File "/home/ace/.local/share/virtualenvs/flask_api-NEe1upaw/lib/python3.6/site-packages/sqlalchemy/orm/query.py", line 3007, in __getitem__
    return list(res)
  File "/home/ace/.local/share/virtualenvs/flask_api-NEe1upaw/lib/python3.6/site-packages/sqlalchemy/orm/query.py", line 3317, in __iter__
    return self._execute_and_instances(context)
  File "/home/ace/.local/share/virtualenvs/flask_api-NEe1upaw/lib/python3.6/site-packages/sqlalchemy/orm/query.py", line 3342, in _execute_and_instances
    result = conn.execute(querycontext.statement, self._params)
  File "/home/ace/.local/share/virtualenvs/flask_api-NEe1upaw/lib/python3.6/site-packages/sqlalchemy/engine/base.py", line 988, in execute
    return meth(self, multiparams, params)
  File "/home/ace/.local/share/virtualenvs/flask_api-NEe1upaw/lib/python3.6/site-packages/sqlalchemy/sql/elements.py", line 287, in _execute_on_connection
    return connection._execute_clauseelement(self, multiparams, params)
  File "/home/ace/.local/share/virtualenvs/flask_api-NEe1upaw/lib/python3.6/site-packages/sqlalchemy/engine/base.py", line 1107, in _execute_clauseelement
    distilled_params,
  File "/home/ace/.local/share/virtualenvs/flask_api-NEe1upaw/lib/python3.6/site-packages/sqlalchemy/engine/base.py", line 1248, in _execute_context
    e, statement, parameters, cursor, context
  File "/home/ace/.local/share/virtualenvs/flask_api-NEe1upaw/lib/python3.6/site-packages/sqlalchemy/engine/base.py", line 1466, in _handle_dbapi_exception
    util.raise_from_cause(sqlalchemy_exception, exc_info)
  File "/home/ace/.local/share/virtualenvs/flask_api-NEe1upaw/lib/python3.6/site-packages/sqlalchemy/util/compat.py", line 383, in raise_from_cause
    reraise(type(exception), exception, tb=exc_tb, cause=cause)
  File "/home/ace/.local/share/virtualenvs/flask_api-NEe1upaw/lib/python3.6/site-packages/sqlalchemy/util/compat.py", line 128, in reraise
    raise value.with_traceback(tb)
  File "/home/ace/.local/share/virtualenvs/flask_api-NEe1upaw/lib/python3.6/site-packages/sqlalchemy/engine/base.py", line 1244, in _execute_context
    cursor, statement, parameters, context
  File "/home/ace/.local/share/virtualenvs/flask_api-NEe1upaw/lib/python3.6/site-packages/sqlalchemy/engine/default.py", line 552, in do_execute
    cursor.execute(statement, parameters)
  File "/home/ace/.local/share/virtualenvs/flask_api-NEe1upaw/lib/python3.6/site-packages/pymysql/cursors.py", line 170, in execute
    result = self._query(query)
  File "/home/ace/.local/share/virtualenvs/flask_api-NEe1upaw/lib/python3.6/site-packages/pymysql/cursors.py", line 328, in _query
    conn.query(q)
  File "/home/ace/.local/share/virtualenvs/flask_api-NEe1upaw/lib/python3.6/site-packages/pymysql/connections.py", line 517, in query
    self._affected_rows = self._read_query_result(unbuffered=unbuffered)
  File "/home/ace/.local/share/virtualenvs/flask_api-NEe1upaw/lib/python3.6/site-packages/pymysql/connections.py", line 732, in _read_query_result
    result.read()
  File "/home/ace/.local/share/virtualenvs/flask_api-NEe1upaw/lib/python3.6/site-packages/pymysql/connections.py", line 1075, in read
    first_packet = self.connection._read_packet()
  File "/home/ace/.local/share/virtualenvs/flask_api-NEe1upaw/lib/python3.6/site-packages/pymysql/connections.py", line 684, in _read_packet
    packet.check_error()
  File "/home/ace/.local/share/virtualenvs/flask_api-NEe1upaw/lib/python3.6/site-packages/pymysql/protocol.py", line 220, in check_error
    err.raise_mysql_exception(self._data)
  File "/home/ace/.local/share/virtualenvs/flask_api-NEe1upaw/lib/python3.6/site-packages/pymysql/err.py", line 109, in raise_mysql_exception
    raise errorclass(errno, errval)
sqlalchemy.exc.InternalError: (pymysql.err.InternalError) (1054, "Unknown column 'user.password' in 'field list'")
[SQL: SELECT user.create_time AS user_create_time, user.password AS user_password, user.update_time AS user_update_time, user.delete_time AS user_delete_time, user.id AS user_id, user.nickname AS user_nickname, user.super AS user_super, user.active AS user_active, user.group_id AS user_group_id 
FROM user 
WHERE user.nickname = %(nickname_1)s 
 LIMIT %(param_1)s]
[parameters: {'nickname_1': 'string', 'param_1': 1}]
(Background on this error at: http://sqlalche.me/e/2j85)
2019-04-17 17:32:19 decorators.py[line:119] error(ERROR): Request(192.168.0.39): [POST] Args: /onecity/v1/register? Body: {}
2019-04-17 17:32:19 decorators.py[line:120] error(ERROR): (pymysql.err.InternalError) (1054, "Unknown column 'user.password' in 'field list'")
[SQL: SELECT user.create_time AS user_create_time, user.password AS user_password, user.update_time AS user_update_time, user.delete_time AS user_delete_time, user.id AS user_id, user.nickname AS user_nickname, user.super AS user_super, user.active AS user_active, user.group_id AS user_group_id 
FROM user 
WHERE user.nickname = %(nickname_1)s 
 LIMIT %(param_1)s]
[parameters: {'nickname_1': 'fuhongzhu', 'param_1': 1}]
(Background on this error at: http://sqlalche.me/e/2j85)
Traceback (most recent call last):
  File "/home/ace/.local/share/virtualenvs/flask_api-NEe1upaw/lib/python3.6/site-packages/sqlalchemy/engine/base.py", line 1244, in _execute_context
    cursor, statement, parameters, context
  File "/home/ace/.local/share/virtualenvs/flask_api-NEe1upaw/lib/python3.6/site-packages/sqlalchemy/engine/default.py", line 552, in do_execute
    cursor.execute(statement, parameters)
  File "/home/ace/.local/share/virtualenvs/flask_api-NEe1upaw/lib/python3.6/site-packages/pymysql/cursors.py", line 170, in execute
    result = self._query(query)
  File "/home/ace/.local/share/virtualenvs/flask_api-NEe1upaw/lib/python3.6/site-packages/pymysql/cursors.py", line 328, in _query
    conn.query(q)
  File "/home/ace/.local/share/virtualenvs/flask_api-NEe1upaw/lib/python3.6/site-packages/pymysql/connections.py", line 517, in query
    self._affected_rows = self._read_query_result(unbuffered=unbuffered)
  File "/home/ace/.local/share/virtualenvs/flask_api-NEe1upaw/lib/python3.6/site-packages/pymysql/connections.py", line 732, in _read_query_result
    result.read()
  File "/home/ace/.local/share/virtualenvs/flask_api-NEe1upaw/lib/python3.6/site-packages/pymysql/connections.py", line 1075, in read
    first_packet = self.connection._read_packet()
  File "/home/ace/.local/share/virtualenvs/flask_api-NEe1upaw/lib/python3.6/site-packages/pymysql/connections.py", line 684, in _read_packet
    packet.check_error()
  File "/home/ace/.local/share/virtualenvs/flask_api-NEe1upaw/lib/python3.6/site-packages/pymysql/protocol.py", line 220, in check_error
    err.raise_mysql_exception(self._data)
  File "/home/ace/.local/share/virtualenvs/flask_api-NEe1upaw/lib/python3.6/site-packages/pymysql/err.py", line 109, in raise_mysql_exception
    raise errorclass(errno, errval)
pymysql.err.InternalError: (1054, "Unknown column 'user.password' in 'field list'")

The above exception was the direct cause of the following exception:

Traceback (most recent call last):
  File "/home/ace/flask_api/app/onecity_v1/decorators.py", line 106, in wrapper
    return view(*args, **kwargs)
  File "/home/ace/flask_api/app/onecity_v1/decorators.py", line 52, in wrapper
    resp = view(*args, **kwargs)
  File "/home/ace/flask_api/app/onecity_v1/decorators.py", line 44, in wrapper
    return view(*args, **kwargs)
  File "/home/ace/flask_api/app/onecity_v1/api/register.py", line 18, in post
    data = user.post_user(g.json)
  File "/home/ace/flask_api/app/services/user.py", line 11, in post_user
    user = User.find_user(nickname=nickname)
  File "/home/ace/flask_api/app/models/user.py", line 46, in find_user
    return User.query.filter_by(**kwargs).first()
  File "/home/ace/.local/share/virtualenvs/flask_api-NEe1upaw/lib/python3.6/site-packages/sqlalchemy/orm/query.py", line 3215, in first
    ret = list(self[0:1])
  File "/home/ace/.local/share/virtualenvs/flask_api-NEe1upaw/lib/python3.6/site-packages/sqlalchemy/orm/query.py", line 3007, in __getitem__
    return list(res)
  File "/home/ace/.local/share/virtualenvs/flask_api-NEe1upaw/lib/python3.6/site-packages/sqlalchemy/orm/query.py", line 3317, in __iter__
    return self._execute_and_instances(context)
  File "/home/ace/.local/share/virtualenvs/flask_api-NEe1upaw/lib/python3.6/site-packages/sqlalchemy/orm/query.py", line 3342, in _execute_and_instances
    result = conn.execute(querycontext.statement, self._params)
  File "/home/ace/.local/share/virtualenvs/flask_api-NEe1upaw/lib/python3.6/site-packages/sqlalchemy/engine/base.py", line 988, in execute
    return meth(self, multiparams, params)
  File "/home/ace/.local/share/virtualenvs/flask_api-NEe1upaw/lib/python3.6/site-packages/sqlalchemy/sql/elements.py", line 287, in _execute_on_connection
    return connection._execute_clauseelement(self, multiparams, params)
  File "/home/ace/.local/share/virtualenvs/flask_api-NEe1upaw/lib/python3.6/site-packages/sqlalchemy/engine/base.py", line 1107, in _execute_clauseelement
    distilled_params,
  File "/home/ace/.local/share/virtualenvs/flask_api-NEe1upaw/lib/python3.6/site-packages/sqlalchemy/engine/base.py", line 1248, in _execute_context
    e, statement, parameters, cursor, context
  File "/home/ace/.local/share/virtualenvs/flask_api-NEe1upaw/lib/python3.6/site-packages/sqlalchemy/engine/base.py", line 1466, in _handle_dbapi_exception
    util.raise_from_cause(sqlalchemy_exception, exc_info)
  File "/home/ace/.local/share/virtualenvs/flask_api-NEe1upaw/lib/python3.6/site-packages/sqlalchemy/util/compat.py", line 383, in raise_from_cause
    reraise(type(exception), exception, tb=exc_tb, cause=cause)
  File "/home/ace/.local/share/virtualenvs/flask_api-NEe1upaw/lib/python3.6/site-packages/sqlalchemy/util/compat.py", line 128, in reraise
    raise value.with_traceback(tb)
  File "/home/ace/.local/share/virtualenvs/flask_api-NEe1upaw/lib/python3.6/site-packages/sqlalchemy/engine/base.py", line 1244, in _execute_context
    cursor, statement, parameters, context
  File "/home/ace/.local/share/virtualenvs/flask_api-NEe1upaw/lib/python3.6/site-packages/sqlalchemy/engine/default.py", line 552, in do_execute
    cursor.execute(statement, parameters)
  File "/home/ace/.local/share/virtualenvs/flask_api-NEe1upaw/lib/python3.6/site-packages/pymysql/cursors.py", line 170, in execute
    result = self._query(query)
  File "/home/ace/.local/share/virtualenvs/flask_api-NEe1upaw/lib/python3.6/site-packages/pymysql/cursors.py", line 328, in _query
    conn.query(q)
  File "/home/ace/.local/share/virtualenvs/flask_api-NEe1upaw/lib/python3.6/site-packages/pymysql/connections.py", line 517, in query
    self._affected_rows = self._read_query_result(unbuffered=unbuffered)
  File "/home/ace/.local/share/virtualenvs/flask_api-NEe1upaw/lib/python3.6/site-packages/pymysql/connections.py", line 732, in _read_query_result
    result.read()
  File "/home/ace/.local/share/virtualenvs/flask_api-NEe1upaw/lib/python3.6/site-packages/pymysql/connections.py", line 1075, in read
    first_packet = self.connection._read_packet()
  File "/home/ace/.local/share/virtualenvs/flask_api-NEe1upaw/lib/python3.6/site-packages/pymysql/connections.py", line 684, in _read_packet
    packet.check_error()
  File "/home/ace/.local/share/virtualenvs/flask_api-NEe1upaw/lib/python3.6/site-packages/pymysql/protocol.py", line 220, in check_error
    err.raise_mysql_exception(self._data)
  File "/home/ace/.local/share/virtualenvs/flask_api-NEe1upaw/lib/python3.6/site-packages/pymysql/err.py", line 109, in raise_mysql_exception
    raise errorclass(errno, errval)
sqlalchemy.exc.InternalError: (pymysql.err.InternalError) (1054, "Unknown column 'user.password' in 'field list'")
[SQL: SELECT user.create_time AS user_create_time, user.password AS user_password, user.update_time AS user_update_time, user.delete_time AS user_delete_time, user.id AS user_id, user.nickname AS user_nickname, user.super AS user_super, user.active AS user_active, user.group_id AS user_group_id 
FROM user 
WHERE user.nickname = %(nickname_1)s 
 LIMIT %(param_1)s]
[parameters: {'nickname_1': 'fuhongzhu', 'param_1': 1}]
(Background on this error at: http://sqlalche.me/e/2j85)
2019-04-17 17:42:27 decorators.py[line:119] error(ERROR): Request(192.168.0.39): [POST] Args: /onecity/v1/register? Body: {}
2019-04-17 17:42:27 decorators.py[line:120] error(ERROR): 422 Unprocessable Entity: The request was well-formed but was unable to be followed due to semantic errors.
Traceback (most recent call last):
  File "/home/ace/flask_api/app/onecity_v1/decorators.py", line 106, in wrapper
    return view(*args, **kwargs)
  File "/home/ace/flask_api/app/onecity_v1/decorators.py", line 52, in wrapper
    resp = view(*args, **kwargs)
  File "/home/ace/flask_api/app/onecity_v1/decorators.py", line 42, in wrapper
    abort(422, message='Unprocessable Entity', errors=errors)
  File "/home/ace/.local/share/virtualenvs/flask_api-NEe1upaw/lib/python3.6/site-packages/flask_restful/__init__.py", line 29, in abort
    original_flask_abort(http_status_code)
  File "/home/ace/.local/share/virtualenvs/flask_api-NEe1upaw/lib/python3.6/site-packages/werkzeug/exceptions.py", line 752, in abort
    return _aborter(status, *args, **kwargs)
  File "/home/ace/.local/share/virtualenvs/flask_api-NEe1upaw/lib/python3.6/site-packages/werkzeug/exceptions.py", line 733, in __call__
    raise self.mapping[code](*args, **kwargs)
werkzeug.exceptions.UnprocessableEntity: 422 Unprocessable Entity: The request was well-formed but was unable to be followed due to semantic errors.
2019-04-17 18:05:57 decorators.py[line:120] error(ERROR): Request(192.168.0.39): [POST] Args: /onecity/v1/register? Body: {}
2019-04-17 18:05:57 decorators.py[line:121] error(ERROR): 422 Unprocessable Entity: The request was well-formed but was unable to be followed due to semantic errors.
Traceback (most recent call last):
  File "/home/ace/flask_api/app/onecity_v1/decorators.py", line 107, in wrapper
    return view(*args, **kwargs)
  File "/home/ace/flask_api/app/onecity_v1/decorators.py", line 53, in wrapper
    resp = view(*args, **kwargs)
  File "/home/ace/flask_api/app/onecity_v1/decorators.py", line 42, in wrapper
    abort(422, message='Unprocessable Entity', errors=errors)
  File "/home/ace/.local/share/virtualenvs/flask_api-NEe1upaw/lib/python3.6/site-packages/flask_restful/__init__.py", line 29, in abort
    original_flask_abort(http_status_code)
  File "/home/ace/.local/share/virtualenvs/flask_api-NEe1upaw/lib/python3.6/site-packages/werkzeug/exceptions.py", line 752, in abort
    return _aborter(status, *args, **kwargs)
  File "/home/ace/.local/share/virtualenvs/flask_api-NEe1upaw/lib/python3.6/site-packages/werkzeug/exceptions.py", line 733, in __call__
    raise self.mapping[code](*args, **kwargs)
werkzeug.exceptions.UnprocessableEntity: 422 Unprocessable Entity: The request was well-formed but was unable to be followed due to semantic errors.
2019-04-17 18:06:30 decorators.py[line:121] error(ERROR): Request(192.168.0.39): [POST] Args: /onecity/v1/register? Body: {}
2019-04-17 18:06:30 decorators.py[line:122] error(ERROR): exceptions must derive from BaseException
Traceback (most recent call last):
  File "/home/ace/flask_api/app/onecity_v1/decorators.py", line 108, in wrapper
    return view(*args, **kwargs)
  File "/home/ace/flask_api/app/onecity_v1/decorators.py", line 54, in wrapper
    resp = view(*args, **kwargs)
  File "/home/ace/flask_api/app/onecity_v1/decorators.py", line 43, in wrapper
    raise errors
TypeError: exceptions must derive from BaseException
2019-04-17 18:06:33 decorators.py[line:121] error(ERROR): Request(192.168.0.39): [POST] Args: /onecity/v1/register? Body: {}
2019-04-17 18:06:33 decorators.py[line:122] error(ERROR): exceptions must derive from BaseException
Traceback (most recent call last):
  File "/home/ace/flask_api/app/onecity_v1/decorators.py", line 108, in wrapper
    return view(*args, **kwargs)
  File "/home/ace/flask_api/app/onecity_v1/decorators.py", line 54, in wrapper
    resp = view(*args, **kwargs)
  File "/home/ace/flask_api/app/onecity_v1/decorators.py", line 43, in wrapper
    raise errors
TypeError: exceptions must derive from BaseException
2019-04-17 18:06:45 decorators.py[line:121] error(ERROR): Request(192.168.0.39): [POST] Args: /onecity/v1/register? Body: {}
2019-04-17 18:06:45 decorators.py[line:122] error(ERROR): exceptions must derive from BaseException
Traceback (most recent call last):
  File "/home/ace/flask_api/app/onecity_v1/decorators.py", line 108, in wrapper
    return view(*args, **kwargs)
  File "/home/ace/flask_api/app/onecity_v1/decorators.py", line 54, in wrapper
    resp = view(*args, **kwargs)
  File "/home/ace/flask_api/app/onecity_v1/decorators.py", line 43, in wrapper
    raise errors
TypeError: exceptions must derive from BaseException
2019-04-17 18:08:04 decorators.py[line:121] error(ERROR): Request(192.168.0.39): [POST] Args: /onecity/v1/register? Body: {}
2019-04-17 18:08:04 decorators.py[line:122] error(ERROR): exceptions must derive from BaseException
Traceback (most recent call last):
  File "/home/ace/flask_api/app/onecity_v1/decorators.py", line 108, in wrapper
    return view(*args, **kwargs)
  File "/home/ace/flask_api/app/onecity_v1/decorators.py", line 54, in wrapper
    resp = view(*args, **kwargs)
  File "/home/ace/flask_api/app/onecity_v1/decorators.py", line 43, in wrapper
    raise errors
TypeError: exceptions must derive from BaseException
2019-04-17 18:08:07 decorators.py[line:121] error(ERROR): Request(192.168.0.39): [POST] Args: /onecity/v1/register? Body: {}
2019-04-17 18:08:07 decorators.py[line:122] error(ERROR): exceptions must derive from BaseException
Traceback (most recent call last):
  File "/home/ace/flask_api/app/onecity_v1/decorators.py", line 108, in wrapper
    return view(*args, **kwargs)
  File "/home/ace/flask_api/app/onecity_v1/decorators.py", line 54, in wrapper
    resp = view(*args, **kwargs)
  File "/home/ace/flask_api/app/onecity_v1/decorators.py", line 43, in wrapper
    raise errors
TypeError: exceptions must derive from BaseException
2019-04-17 18:08:11 decorators.py[line:121] error(ERROR): Request(192.168.0.39): [POST] Args: /onecity/v1/register? Body: {}
2019-04-17 18:08:11 decorators.py[line:122] error(ERROR): exceptions must derive from BaseException
Traceback (most recent call last):
  File "/home/ace/flask_api/app/onecity_v1/decorators.py", line 108, in wrapper
    return view(*args, **kwargs)
  File "/home/ace/flask_api/app/onecity_v1/decorators.py", line 54, in wrapper
    resp = view(*args, **kwargs)
  File "/home/ace/flask_api/app/onecity_v1/decorators.py", line 43, in wrapper
    raise errors
TypeError: exceptions must derive from BaseException
2019-04-17 18:08:12 decorators.py[line:121] error(ERROR): Request(192.168.0.39): [POST] Args: /onecity/v1/register? Body: {}
2019-04-17 18:08:12 decorators.py[line:122] error(ERROR): exceptions must derive from BaseException
Traceback (most recent call last):
  File "/home/ace/flask_api/app/onecity_v1/decorators.py", line 108, in wrapper
    return view(*args, **kwargs)
  File "/home/ace/flask_api/app/onecity_v1/decorators.py", line 54, in wrapper
    resp = view(*args, **kwargs)
  File "/home/ace/flask_api/app/onecity_v1/decorators.py", line 43, in wrapper
    raise errors
TypeError: exceptions must derive from BaseException
2019-04-17 18:08:13 decorators.py[line:121] error(ERROR): Request(192.168.0.39): [POST] Args: /onecity/v1/register? Body: {}
2019-04-17 18:08:13 decorators.py[line:122] error(ERROR): exceptions must derive from BaseException
Traceback (most recent call last):
  File "/home/ace/flask_api/app/onecity_v1/decorators.py", line 108, in wrapper
    return view(*args, **kwargs)
  File "/home/ace/flask_api/app/onecity_v1/decorators.py", line 54, in wrapper
    resp = view(*args, **kwargs)
  File "/home/ace/flask_api/app/onecity_v1/decorators.py", line 43, in wrapper
    raise errors
TypeError: exceptions must derive from BaseException
2019-04-17 18:19:09 decorators.py[line:44] error(ERROR): Request(192.168.0.39): [POST] Args: /onecity/v1/register? Body: {}
2019-04-17 18:19:09 decorators.py[line:45] error(ERROR): ["'st' does not match '^[A-Za-z0-9_*&$#@]{6,22}$'", "'st' is too short"]
NoneType: None
2019-04-17 18:21:00 decorators.py[line:45] error(ERROR): ["'st' does not match '^[A-Za-z0-9_*&$#@]{6,22}$'", "'st' is too short"]
NoneType: None
2019-04-17 18:21:37 decorators.py[line:46] error(ERROR): ["'st' does not match '^[A-Za-z0-9_*&$#@]{6,22}$'", "'st' is too short"]
2019-04-17 18:22:51 decorators.py[line:46] error(ERROR): ["'st' does not match '^[A-Za-z0-9_*&$#@]{6,22}$'", "'st' is too short"]
2019-04-17 18:24:13 decorators.py[line:46] error(ERROR): ["'st' does not match '^[A-Za-z0-9_*&$#@]{6,22}$'", "'st' is too short"]
2019-04-17 18:25:24 decorators.py[line:43] error(ERROR): Request(192.168.0.39): [POST] Args: /onecity/v1/register? Body: {}
2019-04-17 18:25:24 decorators.py[line:44] error(ERROR): ["'st' does not match '^[A-Za-z0-9_*&$#@]{6,22}$'", "'st' is too short"]
2019-04-17 18:45:30 decorators.py[line:43] error(ERROR): Request(192.168.0.39): [POST] Args: /onecity/v1/register? Body: {}
2019-04-17 18:45:30 decorators.py[line:44] error(ERROR): ["'st' does not match '^[A-Za-z0-9_*&$#@]{6,22}$'", "'st' is too short"]
2019-04-17 18:47:53 decorators.py[line:44] error(ERROR): Request(192.168.0.39): [POST] Args: /onecity/v1/register? Body: {}
2019-04-17 18:47:53 decorators.py[line:45] error(ERROR): ["'st' does not match '^[A-Za-z0-9_*&$#@]{6,22}$'", "'st' is too short"]
2019-04-17 18:48:31 decorators.py[line:44] error(ERROR): Request(192.168.0.39): [POST] Args: /onecity/v1/register? Body: {}
2019-04-17 18:48:31 decorators.py[line:45] error(ERROR): ["'st' does not match '^[A-Za-z0-9_*&$#@]{6,22}$'", "'st' is too short"]
2019-04-17 18:50:37 decorators.py[line:45] error(ERROR): Request(192.168.0.39): [POST] Args: /onecity/v1/register? Body: {}
2019-04-17 18:50:37 decorators.py[line:46] error(ERROR): ["'st' does not match '^[A-Za-z0-9_*&$#@]{6,22}$'", "'st' is too short"]
2019-04-17 18:51:12 decorators.py[line:45] error(ERROR): Request(192.168.0.39): [POST] Args: /onecity/v1/register? Body: {}
2019-04-17 18:51:12 decorators.py[line:46] error(ERROR): ["'st' does not match '^[A-Za-z0-9_*&$#@]{6,22}$'", "'st' is too short"]
2019-04-17 18:52:09 decorators.py[line:45] error(ERROR): Request(192.168.0.39): [POST] Args: /onecity/v1/register? Body: {}
2019-04-17 18:52:09 decorators.py[line:46] error(ERROR): ["'st' does not match '^[A-Za-z0-9_*&$#@]{6,22}$'", "'st' is too short"]
2019-04-17 18:59:29 decorators.py[line:129] error(ERROR): Request(192.168.0.39): [POST] Args: /onecity/v1/register? Body: {}
2019-04-17 18:59:29 decorators.py[line:130] error(ERROR): name 'request' is not defined
Traceback (most recent call last):
  File "/home/ace/flask_api/app/onecity_v1/decorators.py", line 114, in wrapper
    return view(*args, **kwargs)
  File "/home/ace/flask_api/app/onecity_v1/decorators.py", line 59, in wrapper
    resp = view(*args, **kwargs)
  File "/home/ace/flask_api/app/onecity_v1/decorators.py", line 27, in wrapper
    endpoint = request.endpoint.partition('.')[-1]
NameError: name 'request' is not defined
2019-04-17 18:59:52 decorators.py[line:129] error(ERROR): Request(192.168.0.39): [POST] Args: /onecity/v1/register? Body: {}
2019-04-17 18:59:52 decorators.py[line:130] error(ERROR): name 'request' is not defined
Traceback (most recent call last):
  File "/home/ace/flask_api/app/onecity_v1/decorators.py", line 114, in wrapper
    return view(*args, **kwargs)
  File "/home/ace/flask_api/app/onecity_v1/decorators.py", line 59, in wrapper
    resp = view(*args, **kwargs)
  File "/home/ace/flask_api/app/onecity_v1/decorators.py", line 27, in wrapper
    endpoint = request.endpoint.partition('.')[-1]
NameError: name 'request' is not defined
2019-04-17 19:01:05 decorators.py[line:129] error(ERROR): Request(192.168.0.39): [POST] Args: /onecity/v1/register? Body: {}
2019-04-17 19:01:05 decorators.py[line:130] error(ERROR): name 'request' is not defined
Traceback (most recent call last):
  File "/home/ace/flask_api/app/onecity_v1/decorators.py", line 114, in wrapper
    return view(*args, **kwargs)
  File "/home/ace/flask_api/app/onecity_v1/decorators.py", line 59, in wrapper
    resp = view(*args, **kwargs)
  File "/home/ace/flask_api/app/onecity_v1/decorators.py", line 27, in wrapper
    endpoint = request.endpoint.partition('.')[-1]
NameError: name 'request' is not defined
2019-04-17 19:02:01 decorators.py[line:129] error(ERROR): Request(192.168.0.39): [POST] Args: /onecity/v1/register? Body: {}
2019-04-17 19:02:01 decorators.py[line:130] error(ERROR): name 'request' is not defined
Traceback (most recent call last):
  File "/home/ace/flask_api/app/onecity_v1/decorators.py", line 114, in wrapper
    return view(*args, **kwargs)
  File "/home/ace/flask_api/app/onecity_v1/decorators.py", line 59, in wrapper
    resp = view(*args, **kwargs)
  File "/home/ace/flask_api/app/onecity_v1/decorators.py", line 27, in wrapper
    endpoint = request.endpoint.partition('.')[-1]
NameError: name 'request' is not defined
2019-04-17 19:02:38 decorators.py[line:129] error(ERROR): Request(192.168.0.39): [POST] Args: /onecity/v1/register? Body: {}
2019-04-17 19:02:38 decorators.py[line:130] error(ERROR): name 'request' is not defined
Traceback (most recent call last):
  File "/home/ace/flask_api/app/onecity_v1/decorators.py", line 114, in wrapper
    return view(*args, **kwargs)
  File "/home/ace/flask_api/app/onecity_v1/decorators.py", line 59, in wrapper
    resp = view(*args, **kwargs)
  File "/home/ace/flask_api/app/onecity_v1/decorators.py", line 27, in wrapper
    endpoint = request.endpoint.partition('.')[-1]
NameError: name 'request' is not defined
2019-04-17 19:04:39 decorators.py[line:129] error(ERROR): Request(192.168.0.39): [POST] Args: /onecity/v1/register? Body: {}
2019-04-17 19:04:39 decorators.py[line:130] error(ERROR): name 'request' is not defined
Traceback (most recent call last):
  File "/home/ace/flask_api/app/onecity_v1/decorators.py", line 114, in wrapper
    return view(*args, **kwargs)
  File "/home/ace/flask_api/app/onecity_v1/decorators.py", line 59, in wrapper
    resp = view(*args, **kwargs)
  File "/home/ace/flask_api/app/onecity_v1/decorators.py", line 27, in wrapper
    endpoint = request.endpoint.partition('.')[-1]
NameError: name 'request' is not defined
2019-04-17 19:05:09 decorators.py[line:129] error(ERROR): Request(192.168.0.39): [POST] Args: /onecity/v1/register? Body: {}
2019-04-17 19:05:09 decorators.py[line:130] error(ERROR): name 'request' is not defined
Traceback (most recent call last):
  File "/home/ace/flask_api/app/onecity_v1/decorators.py", line 114, in wrapper
    return view(*args, **kwargs)
  File "/home/ace/flask_api/app/onecity_v1/decorators.py", line 59, in wrapper
    resp = view(*args, **kwargs)
  File "/home/ace/flask_api/app/onecity_v1/decorators.py", line 27, in wrapper
    endpoint = request.endpoint.partition('.')[-1]
NameError: name 'request' is not defined
2019-04-17 19:20:12 decorators.py[line:42] error(ERROR): Request(192.168.0.39): [POST] /onecity/v1/register? Args: {} Body: {'nickname': 'string', 'password': 'g'}
2019-04-17 19:25:09 decorators.py[line:41] error(ERROR): Request(192.168.0.39): [POST] /onecity/v1/register? Args: {} Body: {'nickname': 'string', 'password': 'g'}
2019-04-17 19:25:26 decorators.py[line:41] error(ERROR): Request(192.168.0.39): [POST] /onecity/v1/register? Args: {} Body: {'nickname': 'string', 'password': 'g'}
2019-04-17 19:25:33 decorators.py[line:41] error(ERROR): Request(192.168.0.39): [POST] /onecity/v1/register? Args: {} Body: {'nickname': 'string', 'password': 'g'}
2019-04-17 19:25:49 decorators.py[line:41] error(ERROR): Request(192.168.0.39): [POST] /onecity/v1/register? Args: {} Body: {'nickname': 'string', 'password': 'g'}
2019-04-17 19:30:47 decorators.py[line:41] error(ERROR): Request(192.168.0.39): [POST] /onecity/v1/register? Args: {} Body: {'nickname': 'string', 'password': 'g'}
2019-04-17 19:31:29 decorators.py[line:41] error(ERROR): Request(192.168.0.39): [POST] /onecity/v1/register? Args: {} Body: {'nickname': 'string', 'password': 'g'}
2019-04-17 19:33:40 decorators.py[line:41] error(ERROR): Request(192.168.0.39): [POST] /onecity/v1/register? Args: {} Body: {'nickname': 'string', 'password': 'g'}
2019-04-17 19:34:09 decorators.py[line:41] error(ERROR): Request(192.168.0.39): [POST] /onecity/v1/register? Args: {} Body: {'nickname': 'string', 'password': 'g'}
