2019-04-16 21:30:43 decorators.py[line:89] error(ERROR): Request(192.168.0.39): [GET] Args: /onecity/v1/users? Body: {}
2019-04-16 21:30:43 decorators.py[line:90] error(ERROR): (pymysql.err.IntegrityError) (1062, "Duplicate entry 'yekai' for key 'nickname'")
[SQL: INSERT INTO user (create_time, update_time, delete_time, nickname, super, active) VALUES (%(create_time)s, %(update_time)s, %(delete_time)s, %(nickname)s, %(super)s, %(active)s)]
[parameters: {'create_time': datetime.datetime(2019, 4, 16, 21, 30, 43, 669742), 'update_time': datetime.datetime(2019, 4, 16, 21, 30, 43, 669794), 'delete_time': None, 'nickname': 'yekai', 'super': 1, 'active': 1}]
(Background on this error at: http://sqlalche.me/e/gkpj)
Traceback (most recent call last):
  File "/home/ace/.local/share/virtualenvs/flask_api-NEe1upaw/lib/python3.6/site-packages/sqlalchemy/engine/base.py", line 1244, in _execute_context
    cursor, statement, parameters, context
  File "/home/ace/.local/share/virtualenvs/flask_api-NEe1upaw/lib/python3.6/site-packages/sqlalchemy/engine/default.py", line 552, in do_execute
    cursor.execute(statement, parameters)
  File "/home/ace/.local/share/virtualenvs/flask_api-NEe1upaw/lib/python3.6/site-packages/pymysql/cursors.py", line 170, in execute
    result = self._query(query)
  File "/home/ace/.local/share/virtualenvs/flask_api-NEe1upaw/lib/python3.6/site-packages/pymysql/cursors.py", line 328, in _query
    conn.query(q)
  File "/home/ace/.local/share/virtualenvs/flask_api-NEe1upaw/lib/python3.6/site-packages/pymysql/connections.py", line 517, in query
    self._affected_rows = self._read_query_result(unbuffered=unbuffered)
  File "/home/ace/.local/share/virtualenvs/flask_api-NEe1upaw/lib/python3.6/site-packages/pymysql/connections.py", line 732, in _read_query_result
    result.read()
  File "/home/ace/.local/share/virtualenvs/flask_api-NEe1upaw/lib/python3.6/site-packages/pymysql/connections.py", line 1075, in read
    first_packet = self.connection._read_packet()
  File "/home/ace/.local/share/virtualenvs/flask_api-NEe1upaw/lib/python3.6/site-packages/pymysql/connections.py", line 684, in _read_packet
    packet.check_error()
  File "/home/ace/.local/share/virtualenvs/flask_api-NEe1upaw/lib/python3.6/site-packages/pymysql/protocol.py", line 220, in check_error
    err.raise_mysql_exception(self._data)
  File "/home/ace/.local/share/virtualenvs/flask_api-NEe1upaw/lib/python3.6/site-packages/pymysql/err.py", line 109, in raise_mysql_exception
    raise errorclass(errno, errval)
pymysql.err.IntegrityError: (1062, "Duplicate entry 'yekai' for key 'nickname'")

The above exception was the direct cause of the following exception:

Traceback (most recent call last):
  File "/home/ace/flask_api/app/onecity_v1/decorators.py", line 77, in wrapper
    return view(*args, **kwargs)
  File "/home/ace/flask_api/app/onecity_v1/decorators.py", line 108, in wrapper
    return view(*args, **kwargs)
  File "/home/ace/flask_api/app/onecity_v1/validators.py", line 122, in wrapper
    resp = view(*args, **kwargs)
  File "/home/ace/flask_api/app/onecity_v1/validators.py", line 113, in wrapper
    return view(*args, **kwargs)
  File "/home/ace/flask_api/app/onecity_v1/api/users.py", line 19, in get
    user.create(nickname='yekai')
  File "/usr/lib/python3.6/contextlib.py", line 88, in __exit__
    next(self.gen)
  File "/home/ace/flask_api/app/models/__init__.py", line 19, in auto_commit
    raise e
  File "/home/ace/flask_api/app/models/__init__.py", line 15, in auto_commit
    self.session.commit()
  File "/home/ace/.local/share/virtualenvs/flask_api-NEe1upaw/lib/python3.6/site-packages/sqlalchemy/orm/scoping.py", line 162, in do
    return getattr(self.registry(), name)(*args, **kwargs)
  File "/home/ace/.local/share/virtualenvs/flask_api-NEe1upaw/lib/python3.6/site-packages/sqlalchemy/orm/session.py", line 1026, in commit
    self.transaction.commit()
  File "/home/ace/.local/share/virtualenvs/flask_api-NEe1upaw/lib/python3.6/site-packages/sqlalchemy/orm/session.py", line 493, in commit
    self._prepare_impl()
  File "/home/ace/.local/share/virtualenvs/flask_api-NEe1upaw/lib/python3.6/site-packages/sqlalchemy/orm/session.py", line 472, in _prepare_impl
    self.session.flush()
  File "/home/ace/.local/share/virtualenvs/flask_api-NEe1upaw/lib/python3.6/site-packages/sqlalchemy/orm/session.py", line 2451, in flush
    self._flush(objects)
  File "/home/ace/.local/share/virtualenvs/flask_api-NEe1upaw/lib/python3.6/site-packages/sqlalchemy/orm/session.py", line 2589, in _flush
    transaction.rollback(_capture_exception=True)
  File "/home/ace/.local/share/virtualenvs/flask_api-NEe1upaw/lib/python3.6/site-packages/sqlalchemy/util/langhelpers.py", line 68, in __exit__
    compat.reraise(exc_type, exc_value, exc_tb)
  File "/home/ace/.local/share/virtualenvs/flask_api-NEe1upaw/lib/python3.6/site-packages/sqlalchemy/util/compat.py", line 129, in reraise
    raise value
  File "/home/ace/.local/share/virtualenvs/flask_api-NEe1upaw/lib/python3.6/site-packages/sqlalchemy/orm/session.py", line 2549, in _flush
    flush_context.execute()
  File "/home/ace/.local/share/virtualenvs/flask_api-NEe1upaw/lib/python3.6/site-packages/sqlalchemy/orm/unitofwork.py", line 422, in execute
    rec.execute(self)
  File "/home/ace/.local/share/virtualenvs/flask_api-NEe1upaw/lib/python3.6/site-packages/sqlalchemy/orm/unitofwork.py", line 589, in execute
    uow,
  File "/home/ace/.local/share/virtualenvs/flask_api-NEe1upaw/lib/python3.6/site-packages/sqlalchemy/orm/persistence.py", line 245, in save_obj
    insert,
  File "/home/ace/.local/share/virtualenvs/flask_api-NEe1upaw/lib/python3.6/site-packages/sqlalchemy/orm/persistence.py", line 1120, in _emit_insert_statements
    statement, params
  File "/home/ace/.local/share/virtualenvs/flask_api-NEe1upaw/lib/python3.6/site-packages/sqlalchemy/engine/base.py", line 988, in execute
    return meth(self, multiparams, params)
  File "/home/ace/.local/share/virtualenvs/flask_api-NEe1upaw/lib/python3.6/site-packages/sqlalchemy/sql/elements.py", line 287, in _execute_on_connection
    return connection._execute_clauseelement(self, multiparams, params)
  File "/home/ace/.local/share/virtualenvs/flask_api-NEe1upaw/lib/python3.6/site-packages/sqlalchemy/engine/base.py", line 1107, in _execute_clauseelement
    distilled_params,
  File "/home/ace/.local/share/virtualenvs/flask_api-NEe1upaw/lib/python3.6/site-packages/sqlalchemy/engine/base.py", line 1248, in _execute_context
    e, statement, parameters, cursor, context
  File "/home/ace/.local/share/virtualenvs/flask_api-NEe1upaw/lib/python3.6/site-packages/sqlalchemy/engine/base.py", line 1466, in _handle_dbapi_exception
    util.raise_from_cause(sqlalchemy_exception, exc_info)
  File "/home/ace/.local/share/virtualenvs/flask_api-NEe1upaw/lib/python3.6/site-packages/sqlalchemy/util/compat.py", line 383, in raise_from_cause
    reraise(type(exception), exception, tb=exc_tb, cause=cause)
  File "/home/ace/.local/share/virtualenvs/flask_api-NEe1upaw/lib/python3.6/site-packages/sqlalchemy/util/compat.py", line 128, in reraise
    raise value.with_traceback(tb)
  File "/home/ace/.local/share/virtualenvs/flask_api-NEe1upaw/lib/python3.6/site-packages/sqlalchemy/engine/base.py", line 1244, in _execute_context
    cursor, statement, parameters, context
  File "/home/ace/.local/share/virtualenvs/flask_api-NEe1upaw/lib/python3.6/site-packages/sqlalchemy/engine/default.py", line 552, in do_execute
    cursor.execute(statement, parameters)
  File "/home/ace/.local/share/virtualenvs/flask_api-NEe1upaw/lib/python3.6/site-packages/pymysql/cursors.py", line 170, in execute
    result = self._query(query)
  File "/home/ace/.local/share/virtualenvs/flask_api-NEe1upaw/lib/python3.6/site-packages/pymysql/cursors.py", line 328, in _query
    conn.query(q)
  File "/home/ace/.local/share/virtualenvs/flask_api-NEe1upaw/lib/python3.6/site-packages/pymysql/connections.py", line 517, in query
    self._affected_rows = self._read_query_result(unbuffered=unbuffered)
  File "/home/ace/.local/share/virtualenvs/flask_api-NEe1upaw/lib/python3.6/site-packages/pymysql/connections.py", line 732, in _read_query_result
    result.read()
  File "/home/ace/.local/share/virtualenvs/flask_api-NEe1upaw/lib/python3.6/site-packages/pymysql/connections.py", line 1075, in read
    first_packet = self.connection._read_packet()
  File "/home/ace/.local/share/virtualenvs/flask_api-NEe1upaw/lib/python3.6/site-packages/pymysql/connections.py", line 684, in _read_packet
    packet.check_error()
  File "/home/ace/.local/share/virtualenvs/flask_api-NEe1upaw/lib/python3.6/site-packages/pymysql/protocol.py", line 220, in check_error
    err.raise_mysql_exception(self._data)
  File "/home/ace/.local/share/virtualenvs/flask_api-NEe1upaw/lib/python3.6/site-packages/pymysql/err.py", line 109, in raise_mysql_exception
    raise errorclass(errno, errval)
sqlalchemy.exc.IntegrityError: (pymysql.err.IntegrityError) (1062, "Duplicate entry 'yekai' for key 'nickname'")
[SQL: INSERT INTO user (create_time, update_time, delete_time, nickname, super, active) VALUES (%(create_time)s, %(update_time)s, %(delete_time)s, %(nickname)s, %(super)s, %(active)s)]
[parameters: {'create_time': datetime.datetime(2019, 4, 16, 21, 30, 43, 669742), 'update_time': datetime.datetime(2019, 4, 16, 21, 30, 43, 669794), 'delete_time': None, 'nickname': 'yekai', 'super': 1, 'active': 1}]
(Background on this error at: http://sqlalche.me/e/gkpj)
