2019-04-18 09:46:32 decorators.py[line:41] error(ERROR): Request(192.168.0.38): [POST] /onecity/v1/register? Args: {} Body: {'nickname': 'super', 'password': 'super'}
2019-04-18 10:32:34 decorators.py[line:121] error(ERROR): Request(192.168.0.38): [POST] /onecity/v1/login? Args: {} Body: {'nickname': 'string', 'password': 'string'}
2019-04-18 10:32:34 decorators.py[line:122] error(ERROR): (pymysql.err.ProgrammingError) (1064, 'You have an error in your SQL syntax; check the manual that corresponds to your MySQL server version for the right syntax to use near \'\'nickname\': "\'string\'", \'password\': "\'string\'"} \n LIMIT 1\' at line 3')
[SQL: SELECT user.create_time AS user_create_time, user.password AS user_password, user.update_time AS user_update_time, user.delete_time AS user_delete_time, user.id AS user_id, user.nickname AS user_nickname, user.super AS user_super, user.active AS user_active, user.group_id AS user_group_id 
FROM user 
WHERE user.nickname = %(nickname_1)s 
 LIMIT %(param_1)s]
[parameters: {'nickname_1': {'nickname': 'string', 'password': 'string'}, 'param_1': 1}]
(Background on this error at: http://sqlalche.me/e/f405)
Traceback (most recent call last):
  File "/home/ace/.local/share/virtualenvs/flask_api-NEe1upaw/lib/python3.6/site-packages/sqlalchemy/engine/base.py", line 1244, in _execute_context
    cursor, statement, parameters, context
  File "/home/ace/.local/share/virtualenvs/flask_api-NEe1upaw/lib/python3.6/site-packages/sqlalchemy/engine/default.py", line 552, in do_execute
    cursor.execute(statement, parameters)
  File "/home/ace/.local/share/virtualenvs/flask_api-NEe1upaw/lib/python3.6/site-packages/pymysql/cursors.py", line 170, in execute
    result = self._query(query)
  File "/home/ace/.local/share/virtualenvs/flask_api-NEe1upaw/lib/python3.6/site-packages/pymysql/cursors.py", line 328, in _query
    conn.query(q)
  File "/home/ace/.local/share/virtualenvs/flask_api-NEe1upaw/lib/python3.6/site-packages/pymysql/connections.py", line 517, in query
    self._affected_rows = self._read_query_result(unbuffered=unbuffered)
  File "/home/ace/.local/share/virtualenvs/flask_api-NEe1upaw/lib/python3.6/site-packages/pymysql/connections.py", line 732, in _read_query_result
    result.read()
  File "/home/ace/.local/share/virtualenvs/flask_api-NEe1upaw/lib/python3.6/site-packages/pymysql/connections.py", line 1075, in read
    first_packet = self.connection._read_packet()
  File "/home/ace/.local/share/virtualenvs/flask_api-NEe1upaw/lib/python3.6/site-packages/pymysql/connections.py", line 684, in _read_packet
    packet.check_error()
  File "/home/ace/.local/share/virtualenvs/flask_api-NEe1upaw/lib/python3.6/site-packages/pymysql/protocol.py", line 220, in check_error
    err.raise_mysql_exception(self._data)
  File "/home/ace/.local/share/virtualenvs/flask_api-NEe1upaw/lib/python3.6/site-packages/pymysql/err.py", line 109, in raise_mysql_exception
    raise errorclass(errno, errval)
pymysql.err.ProgrammingError: (1064, 'You have an error in your SQL syntax; check the manual that corresponds to your MySQL server version for the right syntax to use near \'\'nickname\': "\'string\'", \'password\': "\'string\'"} \n LIMIT 1\' at line 3')

The above exception was the direct cause of the following exception:

Traceback (most recent call last):
  File "/home/ace/flask_api/app/onecity_v1/decorators.py", line 107, in wrapper
    return view(*args, **kwargs)
  File "/home/ace/flask_api/app/onecity_v1/decorators.py", line 52, in wrapper
    resp = view(*args, **kwargs)
  File "/home/ace/flask_api/app/onecity_v1/decorators.py", line 44, in wrapper
    return view(*args, **kwargs)
  File "/home/ace/flask_api/app/onecity_v1/api/login.py", line 18, in post
    data = user.login(g.json)
  File "/home/ace/flask_api/app/services/user.py", line 19, in login
    user = User.verify(form, '123')
  File "/home/ace/flask_api/app/models/user.py", line 56, in verify
    user = cls.query.filter_by(nickname=nickname).first()
  File "/home/ace/.local/share/virtualenvs/flask_api-NEe1upaw/lib/python3.6/site-packages/sqlalchemy/orm/query.py", line 3215, in first
    ret = list(self[0:1])
  File "/home/ace/.local/share/virtualenvs/flask_api-NEe1upaw/lib/python3.6/site-packages/sqlalchemy/orm/query.py", line 3007, in __getitem__
    return list(res)
  File "/home/ace/.local/share/virtualenvs/flask_api-NEe1upaw/lib/python3.6/site-packages/sqlalchemy/orm/query.py", line 3317, in __iter__
    return self._execute_and_instances(context)
  File "/home/ace/.local/share/virtualenvs/flask_api-NEe1upaw/lib/python3.6/site-packages/sqlalchemy/orm/query.py", line 3342, in _execute_and_instances
    result = conn.execute(querycontext.statement, self._params)
  File "/home/ace/.local/share/virtualenvs/flask_api-NEe1upaw/lib/python3.6/site-packages/sqlalchemy/engine/base.py", line 988, in execute
    return meth(self, multiparams, params)
  File "/home/ace/.local/share/virtualenvs/flask_api-NEe1upaw/lib/python3.6/site-packages/sqlalchemy/sql/elements.py", line 287, in _execute_on_connection
    return connection._execute_clauseelement(self, multiparams, params)
  File "/home/ace/.local/share/virtualenvs/flask_api-NEe1upaw/lib/python3.6/site-packages/sqlalchemy/engine/base.py", line 1107, in _execute_clauseelement
    distilled_params,
  File "/home/ace/.local/share/virtualenvs/flask_api-NEe1upaw/lib/python3.6/site-packages/sqlalchemy/engine/base.py", line 1248, in _execute_context
    e, statement, parameters, cursor, context
  File "/home/ace/.local/share/virtualenvs/flask_api-NEe1upaw/lib/python3.6/site-packages/sqlalchemy/engine/base.py", line 1466, in _handle_dbapi_exception
    util.raise_from_cause(sqlalchemy_exception, exc_info)
  File "/home/ace/.local/share/virtualenvs/flask_api-NEe1upaw/lib/python3.6/site-packages/sqlalchemy/util/compat.py", line 383, in raise_from_cause
    reraise(type(exception), exception, tb=exc_tb, cause=cause)
  File "/home/ace/.local/share/virtualenvs/flask_api-NEe1upaw/lib/python3.6/site-packages/sqlalchemy/util/compat.py", line 128, in reraise
    raise value.with_traceback(tb)
  File "/home/ace/.local/share/virtualenvs/flask_api-NEe1upaw/lib/python3.6/site-packages/sqlalchemy/engine/base.py", line 1244, in _execute_context
    cursor, statement, parameters, context
  File "/home/ace/.local/share/virtualenvs/flask_api-NEe1upaw/lib/python3.6/site-packages/sqlalchemy/engine/default.py", line 552, in do_execute
    cursor.execute(statement, parameters)
  File "/home/ace/.local/share/virtualenvs/flask_api-NEe1upaw/lib/python3.6/site-packages/pymysql/cursors.py", line 170, in execute
    result = self._query(query)
  File "/home/ace/.local/share/virtualenvs/flask_api-NEe1upaw/lib/python3.6/site-packages/pymysql/cursors.py", line 328, in _query
    conn.query(q)
  File "/home/ace/.local/share/virtualenvs/flask_api-NEe1upaw/lib/python3.6/site-packages/pymysql/connections.py", line 517, in query
    self._affected_rows = self._read_query_result(unbuffered=unbuffered)
  File "/home/ace/.local/share/virtualenvs/flask_api-NEe1upaw/lib/python3.6/site-packages/pymysql/connections.py", line 732, in _read_query_result
    result.read()
  File "/home/ace/.local/share/virtualenvs/flask_api-NEe1upaw/lib/python3.6/site-packages/pymysql/connections.py", line 1075, in read
    first_packet = self.connection._read_packet()
  File "/home/ace/.local/share/virtualenvs/flask_api-NEe1upaw/lib/python3.6/site-packages/pymysql/connections.py", line 684, in _read_packet
    packet.check_error()
  File "/home/ace/.local/share/virtualenvs/flask_api-NEe1upaw/lib/python3.6/site-packages/pymysql/protocol.py", line 220, in check_error
    err.raise_mysql_exception(self._data)
  File "/home/ace/.local/share/virtualenvs/flask_api-NEe1upaw/lib/python3.6/site-packages/pymysql/err.py", line 109, in raise_mysql_exception
    raise errorclass(errno, errval)
sqlalchemy.exc.ProgrammingError: (pymysql.err.ProgrammingError) (1064, 'You have an error in your SQL syntax; check the manual that corresponds to your MySQL server version for the right syntax to use near \'\'nickname\': "\'string\'", \'password\': "\'string\'"} \n LIMIT 1\' at line 3')
[SQL: SELECT user.create_time AS user_create_time, user.password AS user_password, user.update_time AS user_update_time, user.delete_time AS user_delete_time, user.id AS user_id, user.nickname AS user_nickname, user.super AS user_super, user.active AS user_active, user.group_id AS user_group_id 
FROM user 
WHERE user.nickname = %(nickname_1)s 
 LIMIT %(param_1)s]
[parameters: {'nickname_1': {'nickname': 'string', 'password': 'string'}, 'param_1': 1}]
(Background on this error at: http://sqlalche.me/e/f405)
2019-04-18 10:33:03 decorators.py[line:121] error(ERROR): Request(192.168.0.38): [POST] /onecity/v1/login? Args: {} Body: {'nickname': 'string', 'password': 'string'}
2019-04-18 10:33:03 decorators.py[line:122] error(ERROR): (pymysql.err.ProgrammingError) (1064, 'You have an error in your SQL syntax; check the manual that corresponds to your MySQL server version for the right syntax to use near \'\'nickname\': "\'string\'", \'password\': "\'string\'"} \n LIMIT 1\' at line 3')
[SQL: SELECT user.create_time AS user_create_time, user.password AS user_password, user.update_time AS user_update_time, user.delete_time AS user_delete_time, user.id AS user_id, user.nickname AS user_nickname, user.super AS user_super, user.active AS user_active, user.group_id AS user_group_id 
FROM user 
WHERE user.nickname = %(nickname_1)s 
 LIMIT %(param_1)s]
[parameters: {'nickname_1': {'nickname': 'string', 'password': 'string'}, 'param_1': 1}]
(Background on this error at: http://sqlalche.me/e/f405)
Traceback (most recent call last):
  File "/home/ace/.local/share/virtualenvs/flask_api-NEe1upaw/lib/python3.6/site-packages/sqlalchemy/engine/base.py", line 1244, in _execute_context
    cursor, statement, parameters, context
  File "/home/ace/.local/share/virtualenvs/flask_api-NEe1upaw/lib/python3.6/site-packages/sqlalchemy/engine/default.py", line 552, in do_execute
    cursor.execute(statement, parameters)
  File "/home/ace/.local/share/virtualenvs/flask_api-NEe1upaw/lib/python3.6/site-packages/pymysql/cursors.py", line 170, in execute
    result = self._query(query)
  File "/home/ace/.local/share/virtualenvs/flask_api-NEe1upaw/lib/python3.6/site-packages/pymysql/cursors.py", line 328, in _query
    conn.query(q)
  File "/home/ace/.local/share/virtualenvs/flask_api-NEe1upaw/lib/python3.6/site-packages/pymysql/connections.py", line 517, in query
    self._affected_rows = self._read_query_result(unbuffered=unbuffered)
  File "/home/ace/.local/share/virtualenvs/flask_api-NEe1upaw/lib/python3.6/site-packages/pymysql/connections.py", line 732, in _read_query_result
    result.read()
  File "/home/ace/.local/share/virtualenvs/flask_api-NEe1upaw/lib/python3.6/site-packages/pymysql/connections.py", line 1075, in read
    first_packet = self.connection._read_packet()
  File "/home/ace/.local/share/virtualenvs/flask_api-NEe1upaw/lib/python3.6/site-packages/pymysql/connections.py", line 684, in _read_packet
    packet.check_error()
  File "/home/ace/.local/share/virtualenvs/flask_api-NEe1upaw/lib/python3.6/site-packages/pymysql/protocol.py", line 220, in check_error
    err.raise_mysql_exception(self._data)
  File "/home/ace/.local/share/virtualenvs/flask_api-NEe1upaw/lib/python3.6/site-packages/pymysql/err.py", line 109, in raise_mysql_exception
    raise errorclass(errno, errval)
pymysql.err.ProgrammingError: (1064, 'You have an error in your SQL syntax; check the manual that corresponds to your MySQL server version for the right syntax to use near \'\'nickname\': "\'string\'", \'password\': "\'string\'"} \n LIMIT 1\' at line 3')

The above exception was the direct cause of the following exception:

Traceback (most recent call last):
  File "/home/ace/flask_api/app/onecity_v1/decorators.py", line 107, in wrapper
    return view(*args, **kwargs)
  File "/home/ace/flask_api/app/onecity_v1/decorators.py", line 52, in wrapper
    resp = view(*args, **kwargs)
  File "/home/ace/flask_api/app/onecity_v1/decorators.py", line 44, in wrapper
    return view(*args, **kwargs)
  File "/home/ace/flask_api/app/onecity_v1/api/login.py", line 18, in post
    data = user.login(g.json)
  File "/home/ace/flask_api/app/services/user.py", line 19, in login
    user = User.verify(form, '123')
  File "/home/ace/flask_api/app/models/user.py", line 56, in verify
    user = cls.query.filter_by(nickname=nickname).first()
  File "/home/ace/.local/share/virtualenvs/flask_api-NEe1upaw/lib/python3.6/site-packages/sqlalchemy/orm/query.py", line 3215, in first
    ret = list(self[0:1])
  File "/home/ace/.local/share/virtualenvs/flask_api-NEe1upaw/lib/python3.6/site-packages/sqlalchemy/orm/query.py", line 3007, in __getitem__
    return list(res)
  File "/home/ace/.local/share/virtualenvs/flask_api-NEe1upaw/lib/python3.6/site-packages/sqlalchemy/orm/query.py", line 3317, in __iter__
    return self._execute_and_instances(context)
  File "/home/ace/.local/share/virtualenvs/flask_api-NEe1upaw/lib/python3.6/site-packages/sqlalchemy/orm/query.py", line 3342, in _execute_and_instances
    result = conn.execute(querycontext.statement, self._params)
  File "/home/ace/.local/share/virtualenvs/flask_api-NEe1upaw/lib/python3.6/site-packages/sqlalchemy/engine/base.py", line 988, in execute
    return meth(self, multiparams, params)
  File "/home/ace/.local/share/virtualenvs/flask_api-NEe1upaw/lib/python3.6/site-packages/sqlalchemy/sql/elements.py", line 287, in _execute_on_connection
    return connection._execute_clauseelement(self, multiparams, params)
  File "/home/ace/.local/share/virtualenvs/flask_api-NEe1upaw/lib/python3.6/site-packages/sqlalchemy/engine/base.py", line 1107, in _execute_clauseelement
    distilled_params,
  File "/home/ace/.local/share/virtualenvs/flask_api-NEe1upaw/lib/python3.6/site-packages/sqlalchemy/engine/base.py", line 1248, in _execute_context
    e, statement, parameters, cursor, context
  File "/home/ace/.local/share/virtualenvs/flask_api-NEe1upaw/lib/python3.6/site-packages/sqlalchemy/engine/base.py", line 1466, in _handle_dbapi_exception
    util.raise_from_cause(sqlalchemy_exception, exc_info)
  File "/home/ace/.local/share/virtualenvs/flask_api-NEe1upaw/lib/python3.6/site-packages/sqlalchemy/util/compat.py", line 383, in raise_from_cause
    reraise(type(exception), exception, tb=exc_tb, cause=cause)
  File "/home/ace/.local/share/virtualenvs/flask_api-NEe1upaw/lib/python3.6/site-packages/sqlalchemy/util/compat.py", line 128, in reraise
    raise value.with_traceback(tb)
  File "/home/ace/.local/share/virtualenvs/flask_api-NEe1upaw/lib/python3.6/site-packages/sqlalchemy/engine/base.py", line 1244, in _execute_context
    cursor, statement, parameters, context
  File "/home/ace/.local/share/virtualenvs/flask_api-NEe1upaw/lib/python3.6/site-packages/sqlalchemy/engine/default.py", line 552, in do_execute
    cursor.execute(statement, parameters)
  File "/home/ace/.local/share/virtualenvs/flask_api-NEe1upaw/lib/python3.6/site-packages/pymysql/cursors.py", line 170, in execute
    result = self._query(query)
  File "/home/ace/.local/share/virtualenvs/flask_api-NEe1upaw/lib/python3.6/site-packages/pymysql/cursors.py", line 328, in _query
    conn.query(q)
  File "/home/ace/.local/share/virtualenvs/flask_api-NEe1upaw/lib/python3.6/site-packages/pymysql/connections.py", line 517, in query
    self._affected_rows = self._read_query_result(unbuffered=unbuffered)
  File "/home/ace/.local/share/virtualenvs/flask_api-NEe1upaw/lib/python3.6/site-packages/pymysql/connections.py", line 732, in _read_query_result
    result.read()
  File "/home/ace/.local/share/virtualenvs/flask_api-NEe1upaw/lib/python3.6/site-packages/pymysql/connections.py", line 1075, in read
    first_packet = self.connection._read_packet()
  File "/home/ace/.local/share/virtualenvs/flask_api-NEe1upaw/lib/python3.6/site-packages/pymysql/connections.py", line 684, in _read_packet
    packet.check_error()
  File "/home/ace/.local/share/virtualenvs/flask_api-NEe1upaw/lib/python3.6/site-packages/pymysql/protocol.py", line 220, in check_error
    err.raise_mysql_exception(self._data)
  File "/home/ace/.local/share/virtualenvs/flask_api-NEe1upaw/lib/python3.6/site-packages/pymysql/err.py", line 109, in raise_mysql_exception
    raise errorclass(errno, errval)
sqlalchemy.exc.ProgrammingError: (pymysql.err.ProgrammingError) (1064, 'You have an error in your SQL syntax; check the manual that corresponds to your MySQL server version for the right syntax to use near \'\'nickname\': "\'string\'", \'password\': "\'string\'"} \n LIMIT 1\' at line 3')
[SQL: SELECT user.create_time AS user_create_time, user.password AS user_password, user.update_time AS user_update_time, user.delete_time AS user_delete_time, user.id AS user_id, user.nickname AS user_nickname, user.super AS user_super, user.active AS user_active, user.group_id AS user_group_id 
FROM user 
WHERE user.nickname = %(nickname_1)s 
 LIMIT %(param_1)s]
[parameters: {'nickname_1': {'nickname': 'string', 'password': 'string'}, 'param_1': 1}]
(Background on this error at: http://sqlalche.me/e/f405)
2019-04-18 10:33:13 decorators.py[line:121] error(ERROR): Request(192.168.0.38): [POST] /onecity/v1/login? Args: {} Body: {'nickname': 'string', 'password': 'string'}
2019-04-18 10:33:13 decorators.py[line:122] error(ERROR): (pymysql.err.ProgrammingError) (1064, 'You have an error in your SQL syntax; check the manual that corresponds to your MySQL server version for the right syntax to use near \'\'nickname\': "\'string\'", \'password\': "\'string\'"} \n LIMIT 1\' at line 3')
[SQL: SELECT user.create_time AS user_create_time, user.password AS user_password, user.update_time AS user_update_time, user.delete_time AS user_delete_time, user.id AS user_id, user.nickname AS user_nickname, user.super AS user_super, user.active AS user_active, user.group_id AS user_group_id 
FROM user 
WHERE user.nickname = %(nickname_1)s 
 LIMIT %(param_1)s]
[parameters: {'nickname_1': {'nickname': 'string', 'password': 'string'}, 'param_1': 1}]
(Background on this error at: http://sqlalche.me/e/f405)
Traceback (most recent call last):
  File "/home/ace/.local/share/virtualenvs/flask_api-NEe1upaw/lib/python3.6/site-packages/sqlalchemy/engine/base.py", line 1244, in _execute_context
    cursor, statement, parameters, context
  File "/home/ace/.local/share/virtualenvs/flask_api-NEe1upaw/lib/python3.6/site-packages/sqlalchemy/engine/default.py", line 552, in do_execute
    cursor.execute(statement, parameters)
  File "/home/ace/.local/share/virtualenvs/flask_api-NEe1upaw/lib/python3.6/site-packages/pymysql/cursors.py", line 170, in execute
    result = self._query(query)
  File "/home/ace/.local/share/virtualenvs/flask_api-NEe1upaw/lib/python3.6/site-packages/pymysql/cursors.py", line 328, in _query
    conn.query(q)
  File "/home/ace/.local/share/virtualenvs/flask_api-NEe1upaw/lib/python3.6/site-packages/pymysql/connections.py", line 517, in query
    self._affected_rows = self._read_query_result(unbuffered=unbuffered)
  File "/home/ace/.local/share/virtualenvs/flask_api-NEe1upaw/lib/python3.6/site-packages/pymysql/connections.py", line 732, in _read_query_result
    result.read()
  File "/home/ace/.local/share/virtualenvs/flask_api-NEe1upaw/lib/python3.6/site-packages/pymysql/connections.py", line 1075, in read
    first_packet = self.connection._read_packet()
  File "/home/ace/.local/share/virtualenvs/flask_api-NEe1upaw/lib/python3.6/site-packages/pymysql/connections.py", line 684, in _read_packet
    packet.check_error()
  File "/home/ace/.local/share/virtualenvs/flask_api-NEe1upaw/lib/python3.6/site-packages/pymysql/protocol.py", line 220, in check_error
    err.raise_mysql_exception(self._data)
  File "/home/ace/.local/share/virtualenvs/flask_api-NEe1upaw/lib/python3.6/site-packages/pymysql/err.py", line 109, in raise_mysql_exception
    raise errorclass(errno, errval)
pymysql.err.ProgrammingError: (1064, 'You have an error in your SQL syntax; check the manual that corresponds to your MySQL server version for the right syntax to use near \'\'nickname\': "\'string\'", \'password\': "\'string\'"} \n LIMIT 1\' at line 3')

The above exception was the direct cause of the following exception:

Traceback (most recent call last):
  File "/home/ace/flask_api/app/onecity_v1/decorators.py", line 107, in wrapper
    return view(*args, **kwargs)
  File "/home/ace/flask_api/app/onecity_v1/decorators.py", line 52, in wrapper
    resp = view(*args, **kwargs)
  File "/home/ace/flask_api/app/onecity_v1/decorators.py", line 44, in wrapper
    return view(*args, **kwargs)
  File "/home/ace/flask_api/app/onecity_v1/api/login.py", line 18, in post
    data = user.login(g.json)
  File "/home/ace/flask_api/app/services/user.py", line 19, in login
    user = User.verify(form, '123')
  File "/home/ace/flask_api/app/models/user.py", line 56, in verify
    user = cls.query.filter_by(nickname=nickname).first()
  File "/home/ace/.local/share/virtualenvs/flask_api-NEe1upaw/lib/python3.6/site-packages/sqlalchemy/orm/query.py", line 3215, in first
    ret = list(self[0:1])
  File "/home/ace/.local/share/virtualenvs/flask_api-NEe1upaw/lib/python3.6/site-packages/sqlalchemy/orm/query.py", line 3007, in __getitem__
    return list(res)
  File "/home/ace/.local/share/virtualenvs/flask_api-NEe1upaw/lib/python3.6/site-packages/sqlalchemy/orm/query.py", line 3317, in __iter__
    return self._execute_and_instances(context)
  File "/home/ace/.local/share/virtualenvs/flask_api-NEe1upaw/lib/python3.6/site-packages/sqlalchemy/orm/query.py", line 3342, in _execute_and_instances
    result = conn.execute(querycontext.statement, self._params)
  File "/home/ace/.local/share/virtualenvs/flask_api-NEe1upaw/lib/python3.6/site-packages/sqlalchemy/engine/base.py", line 988, in execute
    return meth(self, multiparams, params)
  File "/home/ace/.local/share/virtualenvs/flask_api-NEe1upaw/lib/python3.6/site-packages/sqlalchemy/sql/elements.py", line 287, in _execute_on_connection
    return connection._execute_clauseelement(self, multiparams, params)
  File "/home/ace/.local/share/virtualenvs/flask_api-NEe1upaw/lib/python3.6/site-packages/sqlalchemy/engine/base.py", line 1107, in _execute_clauseelement
    distilled_params,
  File "/home/ace/.local/share/virtualenvs/flask_api-NEe1upaw/lib/python3.6/site-packages/sqlalchemy/engine/base.py", line 1248, in _execute_context
    e, statement, parameters, cursor, context
  File "/home/ace/.local/share/virtualenvs/flask_api-NEe1upaw/lib/python3.6/site-packages/sqlalchemy/engine/base.py", line 1466, in _handle_dbapi_exception
    util.raise_from_cause(sqlalchemy_exception, exc_info)
  File "/home/ace/.local/share/virtualenvs/flask_api-NEe1upaw/lib/python3.6/site-packages/sqlalchemy/util/compat.py", line 383, in raise_from_cause
    reraise(type(exception), exception, tb=exc_tb, cause=cause)
  File "/home/ace/.local/share/virtualenvs/flask_api-NEe1upaw/lib/python3.6/site-packages/sqlalchemy/util/compat.py", line 128, in reraise
    raise value.with_traceback(tb)
  File "/home/ace/.local/share/virtualenvs/flask_api-NEe1upaw/lib/python3.6/site-packages/sqlalchemy/engine/base.py", line 1244, in _execute_context
    cursor, statement, parameters, context
  File "/home/ace/.local/share/virtualenvs/flask_api-NEe1upaw/lib/python3.6/site-packages/sqlalchemy/engine/default.py", line 552, in do_execute
    cursor.execute(statement, parameters)
  File "/home/ace/.local/share/virtualenvs/flask_api-NEe1upaw/lib/python3.6/site-packages/pymysql/cursors.py", line 170, in execute
    result = self._query(query)
  File "/home/ace/.local/share/virtualenvs/flask_api-NEe1upaw/lib/python3.6/site-packages/pymysql/cursors.py", line 328, in _query
    conn.query(q)
  File "/home/ace/.local/share/virtualenvs/flask_api-NEe1upaw/lib/python3.6/site-packages/pymysql/connections.py", line 517, in query
    self._affected_rows = self._read_query_result(unbuffered=unbuffered)
  File "/home/ace/.local/share/virtualenvs/flask_api-NEe1upaw/lib/python3.6/site-packages/pymysql/connections.py", line 732, in _read_query_result
    result.read()
  File "/home/ace/.local/share/virtualenvs/flask_api-NEe1upaw/lib/python3.6/site-packages/pymysql/connections.py", line 1075, in read
    first_packet = self.connection._read_packet()
  File "/home/ace/.local/share/virtualenvs/flask_api-NEe1upaw/lib/python3.6/site-packages/pymysql/connections.py", line 684, in _read_packet
    packet.check_error()
  File "/home/ace/.local/share/virtualenvs/flask_api-NEe1upaw/lib/python3.6/site-packages/pymysql/protocol.py", line 220, in check_error
    err.raise_mysql_exception(self._data)
  File "/home/ace/.local/share/virtualenvs/flask_api-NEe1upaw/lib/python3.6/site-packages/pymysql/err.py", line 109, in raise_mysql_exception
    raise errorclass(errno, errval)
sqlalchemy.exc.ProgrammingError: (pymysql.err.ProgrammingError) (1064, 'You have an error in your SQL syntax; check the manual that corresponds to your MySQL server version for the right syntax to use near \'\'nickname\': "\'string\'", \'password\': "\'string\'"} \n LIMIT 1\' at line 3')
[SQL: SELECT user.create_time AS user_create_time, user.password AS user_password, user.update_time AS user_update_time, user.delete_time AS user_delete_time, user.id AS user_id, user.nickname AS user_nickname, user.super AS user_super, user.active AS user_active, user.group_id AS user_group_id 
FROM user 
WHERE user.nickname = %(nickname_1)s 
 LIMIT %(param_1)s]
[parameters: {'nickname_1': {'nickname': 'string', 'password': 'string'}, 'param_1': 1}]
(Background on this error at: http://sqlalche.me/e/f405)
2019-04-18 10:34:18 decorators.py[line:121] error(ERROR): Request(192.168.0.38): [POST] /onecity/v1/login? Args: {} Body: {'nickname': 'string', 'password': 'string'}
2019-04-18 10:34:18 decorators.py[line:122] error(ERROR): (pymysql.err.ProgrammingError) (1064, 'You have an error in your SQL syntax; check the manual that corresponds to your MySQL server version for the right syntax to use near \'\'nickname\': "\'string\'", \'password\': "\'string\'"} \n LIMIT 1\' at line 3')
[SQL: SELECT user.create_time AS user_create_time, user.password AS user_password, user.update_time AS user_update_time, user.delete_time AS user_delete_time, user.id AS user_id, user.nickname AS user_nickname, user.super AS user_super, user.active AS user_active, user.group_id AS user_group_id 
FROM user 
WHERE user.nickname = %(nickname_1)s 
 LIMIT %(param_1)s]
[parameters: {'nickname_1': {'nickname': 'string', 'password': 'string'}, 'param_1': 1}]
(Background on this error at: http://sqlalche.me/e/f405)
Traceback (most recent call last):
  File "/home/ace/.local/share/virtualenvs/flask_api-NEe1upaw/lib/python3.6/site-packages/sqlalchemy/engine/base.py", line 1244, in _execute_context
    cursor, statement, parameters, context
  File "/home/ace/.local/share/virtualenvs/flask_api-NEe1upaw/lib/python3.6/site-packages/sqlalchemy/engine/default.py", line 552, in do_execute
    cursor.execute(statement, parameters)
  File "/home/ace/.local/share/virtualenvs/flask_api-NEe1upaw/lib/python3.6/site-packages/pymysql/cursors.py", line 170, in execute
    result = self._query(query)
  File "/home/ace/.local/share/virtualenvs/flask_api-NEe1upaw/lib/python3.6/site-packages/pymysql/cursors.py", line 328, in _query
    conn.query(q)
  File "/home/ace/.local/share/virtualenvs/flask_api-NEe1upaw/lib/python3.6/site-packages/pymysql/connections.py", line 517, in query
    self._affected_rows = self._read_query_result(unbuffered=unbuffered)
  File "/home/ace/.local/share/virtualenvs/flask_api-NEe1upaw/lib/python3.6/site-packages/pymysql/connections.py", line 732, in _read_query_result
    result.read()
  File "/home/ace/.local/share/virtualenvs/flask_api-NEe1upaw/lib/python3.6/site-packages/pymysql/connections.py", line 1075, in read
    first_packet = self.connection._read_packet()
  File "/home/ace/.local/share/virtualenvs/flask_api-NEe1upaw/lib/python3.6/site-packages/pymysql/connections.py", line 684, in _read_packet
    packet.check_error()
  File "/home/ace/.local/share/virtualenvs/flask_api-NEe1upaw/lib/python3.6/site-packages/pymysql/protocol.py", line 220, in check_error
    err.raise_mysql_exception(self._data)
  File "/home/ace/.local/share/virtualenvs/flask_api-NEe1upaw/lib/python3.6/site-packages/pymysql/err.py", line 109, in raise_mysql_exception
    raise errorclass(errno, errval)
pymysql.err.ProgrammingError: (1064, 'You have an error in your SQL syntax; check the manual that corresponds to your MySQL server version for the right syntax to use near \'\'nickname\': "\'string\'", \'password\': "\'string\'"} \n LIMIT 1\' at line 3')

The above exception was the direct cause of the following exception:

Traceback (most recent call last):
  File "/home/ace/flask_api/app/onecity_v1/decorators.py", line 107, in wrapper
    return view(*args, **kwargs)
  File "/home/ace/flask_api/app/onecity_v1/decorators.py", line 52, in wrapper
    resp = view(*args, **kwargs)
  File "/home/ace/flask_api/app/onecity_v1/decorators.py", line 44, in wrapper
    return view(*args, **kwargs)
  File "/home/ace/flask_api/app/onecity_v1/api/login.py", line 18, in post
    data = user.login(g.json)
  File "/home/ace/flask_api/app/services/user.py", line 19, in login
    user = User.verify(form, '123')
  File "/home/ace/flask_api/app/models/user.py", line 57, in verify
    user = cls.query.filter_by(nickname=nickname).first()
  File "/home/ace/.local/share/virtualenvs/flask_api-NEe1upaw/lib/python3.6/site-packages/sqlalchemy/orm/query.py", line 3215, in first
    ret = list(self[0:1])
  File "/home/ace/.local/share/virtualenvs/flask_api-NEe1upaw/lib/python3.6/site-packages/sqlalchemy/orm/query.py", line 3007, in __getitem__
    return list(res)
  File "/home/ace/.local/share/virtualenvs/flask_api-NEe1upaw/lib/python3.6/site-packages/sqlalchemy/orm/query.py", line 3317, in __iter__
    return self._execute_and_instances(context)
  File "/home/ace/.local/share/virtualenvs/flask_api-NEe1upaw/lib/python3.6/site-packages/sqlalchemy/orm/query.py", line 3342, in _execute_and_instances
    result = conn.execute(querycontext.statement, self._params)
  File "/home/ace/.local/share/virtualenvs/flask_api-NEe1upaw/lib/python3.6/site-packages/sqlalchemy/engine/base.py", line 988, in execute
    return meth(self, multiparams, params)
  File "/home/ace/.local/share/virtualenvs/flask_api-NEe1upaw/lib/python3.6/site-packages/sqlalchemy/sql/elements.py", line 287, in _execute_on_connection
    return connection._execute_clauseelement(self, multiparams, params)
  File "/home/ace/.local/share/virtualenvs/flask_api-NEe1upaw/lib/python3.6/site-packages/sqlalchemy/engine/base.py", line 1107, in _execute_clauseelement
    distilled_params,
  File "/home/ace/.local/share/virtualenvs/flask_api-NEe1upaw/lib/python3.6/site-packages/sqlalchemy/engine/base.py", line 1248, in _execute_context
    e, statement, parameters, cursor, context
  File "/home/ace/.local/share/virtualenvs/flask_api-NEe1upaw/lib/python3.6/site-packages/sqlalchemy/engine/base.py", line 1466, in _handle_dbapi_exception
    util.raise_from_cause(sqlalchemy_exception, exc_info)
  File "/home/ace/.local/share/virtualenvs/flask_api-NEe1upaw/lib/python3.6/site-packages/sqlalchemy/util/compat.py", line 383, in raise_from_cause
    reraise(type(exception), exception, tb=exc_tb, cause=cause)
  File "/home/ace/.local/share/virtualenvs/flask_api-NEe1upaw/lib/python3.6/site-packages/sqlalchemy/util/compat.py", line 128, in reraise
    raise value.with_traceback(tb)
  File "/home/ace/.local/share/virtualenvs/flask_api-NEe1upaw/lib/python3.6/site-packages/sqlalchemy/engine/base.py", line 1244, in _execute_context
    cursor, statement, parameters, context
  File "/home/ace/.local/share/virtualenvs/flask_api-NEe1upaw/lib/python3.6/site-packages/sqlalchemy/engine/default.py", line 552, in do_execute
    cursor.execute(statement, parameters)
  File "/home/ace/.local/share/virtualenvs/flask_api-NEe1upaw/lib/python3.6/site-packages/pymysql/cursors.py", line 170, in execute
    result = self._query(query)
  File "/home/ace/.local/share/virtualenvs/flask_api-NEe1upaw/lib/python3.6/site-packages/pymysql/cursors.py", line 328, in _query
    conn.query(q)
  File "/home/ace/.local/share/virtualenvs/flask_api-NEe1upaw/lib/python3.6/site-packages/pymysql/connections.py", line 517, in query
    self._affected_rows = self._read_query_result(unbuffered=unbuffered)
  File "/home/ace/.local/share/virtualenvs/flask_api-NEe1upaw/lib/python3.6/site-packages/pymysql/connections.py", line 732, in _read_query_result
    result.read()
  File "/home/ace/.local/share/virtualenvs/flask_api-NEe1upaw/lib/python3.6/site-packages/pymysql/connections.py", line 1075, in read
    first_packet = self.connection._read_packet()
  File "/home/ace/.local/share/virtualenvs/flask_api-NEe1upaw/lib/python3.6/site-packages/pymysql/connections.py", line 684, in _read_packet
    packet.check_error()
  File "/home/ace/.local/share/virtualenvs/flask_api-NEe1upaw/lib/python3.6/site-packages/pymysql/protocol.py", line 220, in check_error
    err.raise_mysql_exception(self._data)
  File "/home/ace/.local/share/virtualenvs/flask_api-NEe1upaw/lib/python3.6/site-packages/pymysql/err.py", line 109, in raise_mysql_exception
    raise errorclass(errno, errval)
sqlalchemy.exc.ProgrammingError: (pymysql.err.ProgrammingError) (1064, 'You have an error in your SQL syntax; check the manual that corresponds to your MySQL server version for the right syntax to use near \'\'nickname\': "\'string\'", \'password\': "\'string\'"} \n LIMIT 1\' at line 3')
[SQL: SELECT user.create_time AS user_create_time, user.password AS user_password, user.update_time AS user_update_time, user.delete_time AS user_delete_time, user.id AS user_id, user.nickname AS user_nickname, user.super AS user_super, user.active AS user_active, user.group_id AS user_group_id 
FROM user 
WHERE user.nickname = %(nickname_1)s 
 LIMIT %(param_1)s]
[parameters: {'nickname_1': {'nickname': 'string', 'password': 'string'}, 'param_1': 1}]
(Background on this error at: http://sqlalche.me/e/f405)
2019-04-18 10:34:38 decorators.py[line:121] error(ERROR): Request(192.168.0.38): [POST] /onecity/v1/login? Args: {} Body: {'nickname': 'string', 'password': 'string'}
2019-04-18 10:34:38 decorators.py[line:122] error(ERROR): 'nickname' is an invalid keyword argument for this function
Traceback (most recent call last):
  File "/home/ace/flask_api/app/onecity_v1/decorators.py", line 107, in wrapper
    return view(*args, **kwargs)
  File "/home/ace/flask_api/app/onecity_v1/decorators.py", line 52, in wrapper
    resp = view(*args, **kwargs)
  File "/home/ace/flask_api/app/onecity_v1/decorators.py", line 44, in wrapper
    return view(*args, **kwargs)
  File "/home/ace/flask_api/app/onecity_v1/api/login.py", line 18, in post
    data = user.login(g.json)
  File "/home/ace/flask_api/app/services/user.py", line 19, in login
    user = User.verify(form, '123')
  File "/home/ace/flask_api/app/models/user.py", line 57, in verify
    print(**nickname)
TypeError: 'nickname' is an invalid keyword argument for this function
2019-04-18 17:51:50 decorators.py[line:121] error(ERROR): Request(192.168.0.38): [POST] /onecity/v1/login? Args: {} Body: {'nickname': 'string', 'password': 'string'}
2019-04-18 17:51:50 decorators.py[line:122] error(ERROR): name 'get_token' is not defined
Traceback (most recent call last):
  File "/home/ace/flask_api/app/onecity_v1/decorators.py", line 107, in wrapper
    return view(*args, **kwargs)
  File "/home/ace/flask_api/app/onecity_v1/decorators.py", line 52, in wrapper
    resp = view(*args, **kwargs)
  File "/home/ace/flask_api/app/onecity_v1/decorators.py", line 44, in wrapper
    return view(*args, **kwargs)
  File "/home/ace/flask_api/app/onecity_v1/api/login.py", line 18, in post
    data = user.login(g.json)
  File "/home/ace/flask_api/app/services/user.py", line 22, in login
    get_token(user)
NameError: name 'get_token' is not defined
2019-04-18 17:57:08 decorators.py[line:121] error(ERROR): Request(192.168.0.38): [POST] /onecity/v1/login? Args: {} Body: {'nickname': 'string', 'password': 'string'}
2019-04-18 17:57:08 decorators.py[line:122] error(ERROR): _get_token() missing 1 required positional argument: 'user'
Traceback (most recent call last):
  File "/home/ace/flask_api/app/onecity_v1/decorators.py", line 107, in wrapper
    return view(*args, **kwargs)
  File "/home/ace/flask_api/app/onecity_v1/decorators.py", line 52, in wrapper
    resp = view(*args, **kwargs)
  File "/home/ace/flask_api/app/onecity_v1/decorators.py", line 44, in wrapper
    return view(*args, **kwargs)
  File "/home/ace/flask_api/app/onecity_v1/api/login.py", line 18, in post
    data = user.login(g.json)
  File "/home/ace/flask_api/app/services/user.py", line 22, in login
    token = self._get_token(user)
TypeError: _get_token() missing 1 required positional argument: 'user'
2019-04-18 17:58:10 decorators.py[line:121] error(ERROR): Request(192.168.0.38): [POST] /onecity/v1/login? Args: {} Body: {'nickname': 'string', 'password': 'string'}
2019-04-18 17:58:10 decorators.py[line:122] error(ERROR): _get_token() missing 1 required positional argument: 'user'
Traceback (most recent call last):
  File "/home/ace/flask_api/app/onecity_v1/decorators.py", line 107, in wrapper
    return view(*args, **kwargs)
  File "/home/ace/flask_api/app/onecity_v1/decorators.py", line 52, in wrapper
    resp = view(*args, **kwargs)
  File "/home/ace/flask_api/app/onecity_v1/decorators.py", line 44, in wrapper
    return view(*args, **kwargs)
  File "/home/ace/flask_api/app/onecity_v1/api/login.py", line 18, in post
    data = user.login(g.json)
  File "/home/ace/flask_api/app/services/user.py", line 22, in login
    token = self._get_token(user)
TypeError: _get_token() missing 1 required positional argument: 'user'
2019-04-18 18:47:20 decorators.py[line:141] error(ERROR): Request(192.168.0.38): [POST] /onecity/v1/login? Args: {} Body: {'nickname': 'string', 'password': 'string'}
2019-04-18 18:47:20 decorators.py[line:142] error(ERROR): Object of type 'bytes' is not JSON serializable
Traceback (most recent call last):
  File "/home/ace/flask_api/app/onecity_v1/decorators.py", line 127, in wrapper
    return view(*args, **kwargs)
  File "/home/ace/flask_api/app/onecity_v1/decorators.py", line 110, in wrapper
    json.dumps(resp, cls=JSONEncoder) + '\n',
  File "/home/ace/.local/share/virtualenvs/flask_api-NEe1upaw/lib/python3.6/site-packages/flask/json/__init__.py", line 179, in dumps
    rv = _json.dumps(obj, **kwargs)
  File "/usr/lib/python3.6/json/__init__.py", line 238, in dumps
    **kw).encode(obj)
  File "/usr/lib/python3.6/json/encoder.py", line 199, in encode
    chunks = self.iterencode(o, _one_shot=True)
  File "/usr/lib/python3.6/json/encoder.py", line 257, in iterencode
    return _iterencode(o, 0)
  File "/home/ace/flask_api/app/onecity_v1/validators.py", line 31, in default
    return json.JSONEncoder.default(self, o)
  File "/home/ace/.local/share/virtualenvs/flask_api-NEe1upaw/lib/python3.6/site-packages/flask/json/__init__.py", line 81, in default
    return _json.JSONEncoder.default(self, o)
  File "/usr/lib/python3.6/json/encoder.py", line 180, in default
    o.__class__.__name__)
TypeError: Object of type 'bytes' is not JSON serializable
2019-04-18 18:48:48 decorators.py[line:141] error(ERROR): Request(192.168.0.38): [POST] /onecity/v1/login? Args: {} Body: {'nickname': 'string', 'password': 'string'}
2019-04-18 18:48:48 decorators.py[line:142] error(ERROR): Object of type 'bytes' is not JSON serializable
Traceback (most recent call last):
  File "/home/ace/flask_api/app/onecity_v1/decorators.py", line 127, in wrapper
    return view(*args, **kwargs)
  File "/home/ace/flask_api/app/onecity_v1/decorators.py", line 110, in wrapper
    json.dumps(resp, cls=JSONEncoder) + '\n',
  File "/home/ace/.local/share/virtualenvs/flask_api-NEe1upaw/lib/python3.6/site-packages/flask/json/__init__.py", line 179, in dumps
    rv = _json.dumps(obj, **kwargs)
  File "/usr/lib/python3.6/json/__init__.py", line 238, in dumps
    **kw).encode(obj)
  File "/usr/lib/python3.6/json/encoder.py", line 199, in encode
    chunks = self.iterencode(o, _one_shot=True)
  File "/usr/lib/python3.6/json/encoder.py", line 257, in iterencode
    return _iterencode(o, 0)
  File "/home/ace/flask_api/app/onecity_v1/validators.py", line 31, in default
    return json.JSONEncoder.default(self, o)
  File "/home/ace/.local/share/virtualenvs/flask_api-NEe1upaw/lib/python3.6/site-packages/flask/json/__init__.py", line 81, in default
    return _json.JSONEncoder.default(self, o)
  File "/usr/lib/python3.6/json/encoder.py", line 180, in default
    o.__class__.__name__)
TypeError: Object of type 'bytes' is not JSON serializable
2019-04-18 18:49:22 decorators.py[line:141] error(ERROR): Request(192.168.0.38): [POST] /onecity/v1/login? Args: {} Body: {'nickname': 'string', 'password': 'string'}
2019-04-18 18:49:22 decorators.py[line:142] error(ERROR): Object of type 'bytes' is not JSON serializable
Traceback (most recent call last):
  File "/home/ace/flask_api/app/onecity_v1/decorators.py", line 127, in wrapper
    return view(*args, **kwargs)
  File "/home/ace/flask_api/app/onecity_v1/decorators.py", line 110, in wrapper
    json.dumps(resp, cls=JSONEncoder) + '\n',
  File "/home/ace/.local/share/virtualenvs/flask_api-NEe1upaw/lib/python3.6/site-packages/flask/json/__init__.py", line 179, in dumps
    rv = _json.dumps(obj, **kwargs)
  File "/usr/lib/python3.6/json/__init__.py", line 238, in dumps
    **kw).encode(obj)
  File "/usr/lib/python3.6/json/encoder.py", line 199, in encode
    chunks = self.iterencode(o, _one_shot=True)
  File "/usr/lib/python3.6/json/encoder.py", line 257, in iterencode
    return _iterencode(o, 0)
  File "/home/ace/flask_api/app/onecity_v1/validators.py", line 31, in default
    return json.JSONEncoder.default(self, o)
  File "/home/ace/.local/share/virtualenvs/flask_api-NEe1upaw/lib/python3.6/site-packages/flask/json/__init__.py", line 81, in default
    return _json.JSONEncoder.default(self, o)
  File "/usr/lib/python3.6/json/encoder.py", line 180, in default
    o.__class__.__name__)
TypeError: Object of type 'bytes' is not JSON serializable
2019-04-18 18:49:53 decorators.py[line:141] error(ERROR): Request(192.168.0.38): [POST] /onecity/v1/login? Args: {} Body: {'nickname': 'string', 'password': 'string'}
2019-04-18 18:49:53 decorators.py[line:142] error(ERROR): Object of type 'bytes' is not JSON serializable
Traceback (most recent call last):
  File "/home/ace/flask_api/app/onecity_v1/decorators.py", line 127, in wrapper
    return view(*args, **kwargs)
  File "/home/ace/flask_api/app/onecity_v1/decorators.py", line 110, in wrapper
    json.dumps(resp, cls=JSONEncoder) + '\n',
  File "/home/ace/.local/share/virtualenvs/flask_api-NEe1upaw/lib/python3.6/site-packages/flask/json/__init__.py", line 179, in dumps
    rv = _json.dumps(obj, **kwargs)
  File "/usr/lib/python3.6/json/__init__.py", line 238, in dumps
    **kw).encode(obj)
  File "/usr/lib/python3.6/json/encoder.py", line 199, in encode
    chunks = self.iterencode(o, _one_shot=True)
  File "/usr/lib/python3.6/json/encoder.py", line 257, in iterencode
    return _iterencode(o, 0)
  File "/home/ace/flask_api/app/onecity_v1/validators.py", line 31, in default
    return json.JSONEncoder.default(self, o)
  File "/home/ace/.local/share/virtualenvs/flask_api-NEe1upaw/lib/python3.6/site-packages/flask/json/__init__.py", line 81, in default
    return _json.JSONEncoder.default(self, o)
  File "/usr/lib/python3.6/json/encoder.py", line 180, in default
    o.__class__.__name__)
TypeError: Object of type 'bytes' is not JSON serializable
2019-04-18 18:50:34 decorators.py[line:141] error(ERROR): Request(192.168.0.38): [POST] /onecity/v1/login? Args: {} Body: {'nickname': 'string', 'password': 'string'}
2019-04-18 18:50:34 decorators.py[line:142] error(ERROR): Object of type 'bytes' is not JSON serializable
Traceback (most recent call last):
  File "/home/ace/flask_api/app/onecity_v1/decorators.py", line 127, in wrapper
    return view(*args, **kwargs)
  File "/home/ace/flask_api/app/onecity_v1/decorators.py", line 110, in wrapper
    json.dumps(resp, cls=JSONEncoder) + '\n',
  File "/home/ace/.local/share/virtualenvs/flask_api-NEe1upaw/lib/python3.6/site-packages/flask/json/__init__.py", line 179, in dumps
    rv = _json.dumps(obj, **kwargs)
  File "/usr/lib/python3.6/json/__init__.py", line 238, in dumps
    **kw).encode(obj)
  File "/usr/lib/python3.6/json/encoder.py", line 199, in encode
    chunks = self.iterencode(o, _one_shot=True)
  File "/usr/lib/python3.6/json/encoder.py", line 257, in iterencode
    return _iterencode(o, 0)
  File "/home/ace/flask_api/app/onecity_v1/validators.py", line 31, in default
    return json.JSONEncoder.default(self, o)
  File "/home/ace/.local/share/virtualenvs/flask_api-NEe1upaw/lib/python3.6/site-packages/flask/json/__init__.py", line 81, in default
    return _json.JSONEncoder.default(self, o)
  File "/usr/lib/python3.6/json/encoder.py", line 180, in default
    o.__class__.__name__)
TypeError: Object of type 'bytes' is not JSON serializable
2019-04-18 18:53:32 decorators.py[line:141] error(ERROR): Request(192.168.0.38): [POST] /onecity/v1/login? Args: {} Body: {'nickname': 'string', 'password': 'string'}
2019-04-18 18:53:32 decorators.py[line:142] error(ERROR): Object of type 'bytes' is not JSON serializable
Traceback (most recent call last):
  File "/home/ace/flask_api/app/onecity_v1/decorators.py", line 127, in wrapper
    return view(*args, **kwargs)
  File "/home/ace/flask_api/app/onecity_v1/decorators.py", line 110, in wrapper
    json.dumps(resp, cls=JSONEncoder) + '\n',
  File "/home/ace/.local/share/virtualenvs/flask_api-NEe1upaw/lib/python3.6/site-packages/flask/json/__init__.py", line 179, in dumps
    rv = _json.dumps(obj, **kwargs)
  File "/usr/lib/python3.6/json/__init__.py", line 238, in dumps
    **kw).encode(obj)
  File "/usr/lib/python3.6/json/encoder.py", line 199, in encode
    chunks = self.iterencode(o, _one_shot=True)
  File "/usr/lib/python3.6/json/encoder.py", line 257, in iterencode
    return _iterencode(o, 0)
  File "/home/ace/flask_api/app/onecity_v1/validators.py", line 31, in default
    return json.JSONEncoder.default(self, o)
  File "/home/ace/.local/share/virtualenvs/flask_api-NEe1upaw/lib/python3.6/site-packages/flask/json/__init__.py", line 81, in default
    return _json.JSONEncoder.default(self, o)
  File "/usr/lib/python3.6/json/encoder.py", line 180, in default
    o.__class__.__name__)
TypeError: Object of type 'bytes' is not JSON serializable
2019-04-18 19:08:05 decorators.py[line:141] error(ERROR): Request(192.168.0.38): [GET] /onecity/v1/user/information? Args: {} Body: None
2019-04-18 19:08:05 decorators.py[line:142] error(ERROR): 'Token' object has no attribute 'name'
Traceback (most recent call last):
  File "/home/ace/flask_api/app/onecity_v1/decorators.py", line 127, in wrapper
    return view(*args, **kwargs)
  File "/home/ace/flask_api/app/onecity_v1/decorators.py", line 154, in wrapper
    if g.token.value != redis_client.get('token:{}'.format(g.token.name)):
AttributeError: 'Token' object has no attribute 'name'
2019-04-18 19:09:18 decorators.py[line:141] error(ERROR): Request(192.168.0.38): [GET] /onecity/v1/user/information? Args: {} Body: None
2019-04-18 19:09:18 decorators.py[line:142] error(ERROR): 'Token' object has no attribute 'name'
Traceback (most recent call last):
  File "/home/ace/flask_api/app/onecity_v1/decorators.py", line 127, in wrapper
    return view(*args, **kwargs)
  File "/home/ace/flask_api/app/onecity_v1/decorators.py", line 154, in wrapper
    if g.token.value != redis_client.get('token:{}'.format(g.token.name)):
AttributeError: 'Token' object has no attribute 'name'
2019-04-18 19:09:51 decorators.py[line:142] error(ERROR): Request(192.168.0.38): [GET] /onecity/v1/user/information? Args: {} Body: None
2019-04-18 19:09:51 decorators.py[line:143] error(ERROR): 'Token' object has no attribute 'name'
Traceback (most recent call last):
  File "/home/ace/flask_api/app/onecity_v1/decorators.py", line 128, in wrapper
    return view(*args, **kwargs)
  File "/home/ace/flask_api/app/onecity_v1/decorators.py", line 155, in wrapper
    if g.token.value != redis_client.get('token:{}'.format(g.token.name)):
AttributeError: 'Token' object has no attribute 'name'
2019-04-18 19:12:10 decorators.py[line:142] error(ERROR): Request(192.168.0.38): [GET] /onecity/v1/user/information? Args: {} Body: None
2019-04-18 19:12:10 decorators.py[line:143] error(ERROR): 'Token' object has no attribute 'name'
Traceback (most recent call last):
  File "/home/ace/flask_api/app/onecity_v1/decorators.py", line 128, in wrapper
    return view(*args, **kwargs)
  File "/home/ace/flask_api/app/onecity_v1/decorators.py", line 157, in wrapper
    if g.token.value != redis_client.get('token:{}'.format(g.token.name)):
AttributeError: 'Token' object has no attribute 'name'
2019-04-18 19:12:39 decorators.py[line:142] error(ERROR): Request(192.168.0.38): [GET] /onecity/v1/user/information? Args: {} Body: None
2019-04-18 19:12:39 decorators.py[line:143] error(ERROR): 'Token' object has no attribute 'name'
Traceback (most recent call last):
  File "/home/ace/flask_api/app/onecity_v1/decorators.py", line 128, in wrapper
    return view(*args, **kwargs)
  File "/home/ace/flask_api/app/onecity_v1/decorators.py", line 157, in wrapper
    if g.token.value != redis_client.get('token:{}'.format(g.token.name)):
AttributeError: 'Token' object has no attribute 'name'
2019-04-18 19:13:23 decorators.py[line:142] error(ERROR): Request(192.168.0.38): [GET] /onecity/v1/user/information? Args: {} Body: None
2019-04-18 19:13:23 decorators.py[line:143] error(ERROR): 'Token' object has no attribute 'name'
Traceback (most recent call last):
  File "/home/ace/flask_api/app/onecity_v1/decorators.py", line 128, in wrapper
    return view(*args, **kwargs)
  File "/home/ace/flask_api/app/onecity_v1/decorators.py", line 157, in wrapper
    if g.token.value != redis_client.get('token:{}'.format(g.token.name)):
AttributeError: 'Token' object has no attribute 'name'
2019-04-18 19:13:55 decorators.py[line:142] error(ERROR): Request(192.168.0.38): [GET] /onecity/v1/user/information? Args: {} Body: None
2019-04-18 19:13:55 decorators.py[line:143] error(ERROR): 'Token' object has no attribute 'name'
Traceback (most recent call last):
  File "/home/ace/flask_api/app/onecity_v1/decorators.py", line 128, in wrapper
    return view(*args, **kwargs)
  File "/home/ace/flask_api/app/onecity_v1/decorators.py", line 158, in wrapper
    if g.token.value != redis_client.get('token:{}'.format(g.token.name)):
AttributeError: 'Token' object has no attribute 'name'
2019-04-18 19:14:45 decorators.py[line:142] error(ERROR): Request(192.168.0.38): [GET] /onecity/v1/user/information? Args: {} Body: None
2019-04-18 19:14:45 decorators.py[line:143] error(ERROR): 'Token' object has no attribute 'name'
Traceback (most recent call last):
  File "/home/ace/flask_api/app/onecity_v1/decorators.py", line 128, in wrapper
    return view(*args, **kwargs)
  File "/home/ace/flask_api/app/onecity_v1/decorators.py", line 158, in wrapper
    if g.token.value != redis_client.get('token:{}'.format(g.token.name)):
AttributeError: 'Token' object has no attribute 'name'
2019-04-18 19:15:13 decorators.py[line:142] error(ERROR): Request(192.168.0.38): [GET] /onecity/v1/user/information? Args: {} Body: None
2019-04-18 19:15:13 decorators.py[line:143] error(ERROR): 'Token' object has no attribute 'name'
Traceback (most recent call last):
  File "/home/ace/flask_api/app/onecity_v1/decorators.py", line 128, in wrapper
    return view(*args, **kwargs)
  File "/home/ace/flask_api/app/onecity_v1/decorators.py", line 158, in wrapper
    if g.token.value != redis_client.get('token:{}'.format(g.token.name)):
AttributeError: 'Token' object has no attribute 'name'
2019-04-18 19:44:49 decorators.py[line:144] error(ERROR): Request(192.168.0.38): [POST] /onecity/v1/login? Args: {} Body: {'nickname': 'string', 'password': 'string'}
2019-04-18 19:44:49 decorators.py[line:145] error(ERROR): Object of type 'bytes' is not JSON serializable
Traceback (most recent call last):
  File "/home/ace/flask_api/app/onecity_v1/decorators.py", line 130, in wrapper
    return view(*args, **kwargs)
  File "/home/ace/flask_api/app/onecity_v1/decorators.py", line 113, in wrapper
    json.dumps(resp, cls=JSONEncoder) + '\n',
  File "/home/ace/.local/share/virtualenvs/flask_api-NEe1upaw/lib/python3.6/site-packages/flask/json/__init__.py", line 179, in dumps
    rv = _json.dumps(obj, **kwargs)
  File "/usr/lib/python3.6/json/__init__.py", line 238, in dumps
    **kw).encode(obj)
  File "/usr/lib/python3.6/json/encoder.py", line 199, in encode
    chunks = self.iterencode(o, _one_shot=True)
  File "/usr/lib/python3.6/json/encoder.py", line 257, in iterencode
    return _iterencode(o, 0)
  File "/home/ace/flask_api/app/onecity_v1/validators.py", line 31, in default
    return json.JSONEncoder.default(self, o)
  File "/home/ace/.local/share/virtualenvs/flask_api-NEe1upaw/lib/python3.6/site-packages/flask/json/__init__.py", line 81, in default
    return _json.JSONEncoder.default(self, o)
  File "/usr/lib/python3.6/json/encoder.py", line 180, in default
    o.__class__.__name__)
TypeError: Object of type 'bytes' is not JSON serializable
2019-04-18 19:54:14 decorators.py[line:144] error(ERROR): Request(7:string): [GET] /onecity/v1/user/information? Args: {} Body: None
2019-04-18 19:54:14 decorators.py[line:145] error(ERROR): 'NoneType' object is not callable
Traceback (most recent call last):
  File "/home/ace/flask_api/app/onecity_v1/decorators.py", line 130, in wrapper
    return view(*args, **kwargs)
  File "/home/ace/flask_api/app/onecity_v1/decorators.py", line 160, in wrapper
    g.token.requester()
TypeError: 'NoneType' object is not callable
2019-04-18 19:55:47 decorators.py[line:145] error(ERROR): Request(7:string): [GET] /onecity/v1/user/information? Args: {} Body: None
2019-04-18 19:55:47 decorators.py[line:146] error(ERROR): 'NoneType' object is not callable
Traceback (most recent call last):
  File "/home/ace/flask_api/app/onecity_v1/decorators.py", line 131, in wrapper
    return view(*args, **kwargs)
  File "/home/ace/flask_api/app/onecity_v1/decorators.py", line 161, in wrapper
    g.token.requester()
TypeError: 'NoneType' object is not callable
